{
 "bad": false,
 "new_version": "2.0",
 "new_version_attempts": {
  "2.0": 1
 },
 "new_version_errors": {
  "2.0": "bot error (<a href=\"https://github.com/regro/cf-scripts/actions/runs/13401112323\">bot CI job</a>): main:\nTraceback (most recent call last):\n  File \"/home/runner/work/cf-scripts/cf-scripts/cf-scripts/conda_forge_tick/git_utils.py\", line 207, in _run_git_command\n    p = subprocess.run(\n        ^^^^^^^^^^^^^^^\n  File \"/home/runner/micromamba/envs/cf-scripts/lib/python3.11/subprocess.py\", line 571, in run\n    raise CalledProcessError(retcode, process.args,\nsubprocess.CalledProcessError: Command '['git', 'push', 'https://github.com/regro-cf-autotick-bot/nirtorch-feedstock.git', '2.0_h1e7aa7']' returned non-zero exit status 1.\n\nDuring handling of the above exception, another exception occurred:\n\nTraceback (most recent call last):\n  File \"/home/runner/work/cf-scripts/cf-scripts/cf-scripts/conda_forge_tick/auto_tick.py\", line 744, in _run_migrator_on_feedstock_branch\n    migrator_uid, pr_json = run_with_tmpdir(\n                            ^^^^^^^^^^^^^^^^\n  File \"/home/runner/work/cf-scripts/cf-scripts/cf-scripts/conda_forge_tick/auto_tick.py\", line 451, in run_with_tmpdir\n    return run(\n           ^^^^\n  File \"/home/runner/work/cf-scripts/cf-scripts/cf-scripts/conda_forge_tick/auto_tick.py\", line 619, in run\n    git_backend.push_to_repository(\n  File \"/home/runner/micromamba/envs/cf-scripts/lib/python3.11/contextlib.py\", line 81, in inner\n    return func(*args, **kwds)\n           ^^^^^^^^^^^^^^^^^^^\n  File \"/home/runner/work/cf-scripts/cf-scripts/cf-scripts/conda_forge_tick/git_utils.py\", line 838, in push_to_repository\n    self.cli.push_to_url(git_dir, remote_url, branch)\n  File \"/home/runner/micromamba/envs/cf-scripts/lib/python3.11/contextlib.py\", line 81, in inner\n    return func(*args, **kwds)\n           ^^^^^^^^^^^^^^^^^^^\n  File \"/home/runner/work/cf-scripts/cf-scripts/cf-scripts/conda_forge_tick/git_utils.py\", line 300, in push_to_url\n    self._run_git_command([\"push\", remote_url, branch], git_dir)\n  File \"/home/runner/micromamba/envs/cf-scripts/lib/python3.11/contextlib.py\", line 81, in inner\n    return func(*args, **kwds)\n           ^^^^^^^^^^^^^^^^^^^\n  File \"/home/runner/work/cf-scripts/cf-scripts/cf-scripts/conda_forge_tick/git_utils.py\", line 219, in _run_git_command\n    raise GitCliError(f\"Error running git command: {repr(e)}\")\nconda_forge_tick.git_utils.GitCliError: Error running git command: CalledProcessError(1, ['git', 'push', 'https://github.com/regro-cf-autotick-bot/nirtorch-feedstock.git', '2.0_h1e7aa7'])\n"
 }
}