{
 "bad": false,
 "new_version": "56.0",
 "new_version_attempts": {
  "30.1": 1,
  "30.2": 1,
  "30.6": 1,
  "30.8": 1,
  "48.0-1": 6,
  "49.0": 1,
  "49.1": 1,
  "50.0": 1,
  "50.0-1": 3,
  "50.0-2": 14,
  "51.0": 1,
  "52.0-1": 3,
  "52.0-2": 7,
  "55.0-1": 62,
  "56.0": 1
 },
 "new_version_errors": {
  "48.0-1": "The recipe did not change in the version migration, a URL did not hash, or there is jinja2 syntax the bot cannot handle!\n\nPlease check the URLs in your recipe with version '48.0-1' to make sure they exist!\n\nWe also found the following errors:\n\n - could not hash URL template 'https://github.com/linux-rdma/rdma-core/archive/v{{ version }}.tar.gz'\n",
  "50.0-1": "The recipe did not change in the version migration, a URL did not hash, or there is jinja2 syntax the bot cannot handle!\n\nPlease check the URLs in your recipe with version '50.0-1' to make sure they exist!\n\nWe also found the following errors:\n\n - could not hash URL template 'https://github.com/linux-rdma/rdma-core/archive/v{{ version }}.tar.gz'\n",
  "50.0-2": "The recipe did not change in the version migration, a URL did not hash, or there is jinja2 syntax the bot cannot handle!\n\nPlease check the URLs in your recipe with version '50.0-2' to make sure they exist!\n\nWe also found the following errors:\n\n - could not hash URL template 'https://github.com/linux-rdma/rdma-core/archive/v{{ version }}.tar.gz'\n",
  "52.0-1": "bot error (<a href=\"https://github.com/regro/cf-scripts/actions/runs/9663453987\">bot CI job</a>): main:\nError running migrate-feedstock in container - error VersionMigrationError raised:\n\"The recipe did not change in the version migration, a URL did not hash, or there is jinja2 syntax the bot cannot handle!\n\nPlease check the URLs in your recipe with version '52.0-1' to make sure they exist!\n\nWe also found the following errors:\n\n - could not hash URL template 'https://github.com/linux-rdma/rdma-core/archive/v{{ version }}.tar.gz'\n\"",
  "52.0-2": "bot error (<a href=\"https://github.com/regro/cf-scripts/actions/runs/10032175019\">bot CI job</a>): main:\nError running migrate-feedstock in container - error VersionMigrationError raised:\n\"The recipe did not change in the version migration, a URL did not hash, or there is jinja2 syntax the bot cannot handle!\n\nPlease check the URLs in your recipe with version '52.0-2' to make sure they exist!\n\nWe also found the following errors:\n\n - could not hash URL template 'https://github.com/linux-rdma/rdma-core/archive/v{{ version }}.tar.gz'\n\"",
  "55.0-1": "bot error (<a href=\"https://github.com/regro/cf-scripts/actions/runs/13173187337\">bot CI job</a>): main:\nTraceback (most recent call last):\n  File \"/opt/autotick-bot/conda_forge_tick/container_cli.py\", line 119, in _run_bot_task\n    data = func(attrs=attrs, **kwargs)\n           ^^^^^^^^^^^^^^^^^^^^^^^^^^^\n  File \"/opt/autotick-bot/conda_forge_tick/container_cli.py\", line 225, in _migrate_feedstock\n    data = run_migration_local(\n           ^^^^^^^^^^^^^^^^^^^^\n  File \"/opt/autotick-bot/conda_forge_tick/migration_runner.py\", line 251, in run_migration_local\n    data[\"migrate_return_value\"] = migrator.migrate(\n                                   ^^^^^^^^^^^^^^^^^\n  File \"/opt/autotick-bot/conda_forge_tick/migrators/version.py\", line 254, in migrate\n    raise VersionMigrationError(\nconda_forge_tick.migrators.version.VersionMigrationError: The recipe did not change in the version migration, a URL did not hash, or there is jinja2 syntax the bot cannot handle!\n\nPlease check the URLs in your recipe with version '55.0-1' to make sure they exist!\n\nWe also found the following errors:\n\n - could not hash URL template 'https://github.com/linux-rdma/rdma-core/archive/v{{ version }}.tar.gz'\n\n",
  "56.0": "bot error (<a href=\"https://github.com/regro/cf-scripts/actions/runs/13176498921\">bot CI job</a>): main:\nTraceback (most recent call last):\n  File \"/home/runner/micromamba/envs/cf-scripts/lib/python3.11/site-packages/requests/adapters.py\", line 667, in send\n    resp = conn.urlopen(\n           ^^^^^^^^^^^^^\n  File \"/home/runner/micromamba/envs/cf-scripts/lib/python3.11/site-packages/urllib3/connectionpool.py\", line 896, in urlopen\n    return self.urlopen(\n           ^^^^^^^^^^^^^\n  File \"/home/runner/micromamba/envs/cf-scripts/lib/python3.11/site-packages/urllib3/connectionpool.py\", line 896, in urlopen\n    return self.urlopen(\n           ^^^^^^^^^^^^^\n  File \"/home/runner/micromamba/envs/cf-scripts/lib/python3.11/site-packages/urllib3/connectionpool.py\", line 896, in urlopen\n    return self.urlopen(\n           ^^^^^^^^^^^^^\n  [Previous line repeated 7 more times]\n  File \"/home/runner/micromamba/envs/cf-scripts/lib/python3.11/site-packages/urllib3/connectionpool.py\", line 886, in urlopen\n    retries = retries.increment(method, url, response=response, _pool=self)\n              ^^^^^^^^^^^^^^^^^^^^^^^^^^^^^^^^^^^^^^^^^^^^^^^^^^^^^^^^^^^^^\n  File \"/home/runner/micromamba/envs/cf-scripts/lib/python3.11/site-packages/github/GithubRetry.py\", line 205, in increment\n    return super().increment(method, url, response, error, _pool, _stacktrace)\n           ^^^^^^^^^^^^^^^^^^^^^^^^^^^^^^^^^^^^^^^^^^^^^^^^^^^^^^^^^^^^^^^^^^^\n  File \"/home/runner/micromamba/envs/cf-scripts/lib/python3.11/site-packages/urllib3/util/retry.py\", line 594, in increment\n    raise MaxRetryError(_pool, url, error or ResponseError(cause))\nurllib3.exceptions.MaxRetryError: HTTPSConnectionPool(host='api.github.com', port=443): Max retries exceeded with url: /user (Caused by ResponseError('too many 502 error responses'))\n\nDuring handling of the above exception, another exception occurred:\n\nTraceback (most recent call last):\n  File \"/home/runner/work/cf-scripts/cf-scripts/cf-scripts/conda_forge_tick/auto_tick.py\", line 744, in _run_migrator_on_feedstock_branch\n    migrator_uid, pr_json = run_with_tmpdir(\n                            ^^^^^^^^^^^^^^^^\n  File \"/home/runner/work/cf-scripts/cf-scripts/cf-scripts/conda_forge_tick/auto_tick.py\", line 451, in run_with_tmpdir\n    return run(\n           ^^^^\n  File \"/home/runner/work/cf-scripts/cf-scripts/cf-scripts/conda_forge_tick/auto_tick.py\", line 523, in run\n    if not _prepare_feedstock_repository(\n           ^^^^^^^^^^^^^^^^^^^^^^^^^^^^^^\n  File \"/home/runner/work/cf-scripts/cf-scripts/cf-scripts/conda_forge_tick/auto_tick.py\", line 165, in _prepare_feedstock_repository\n    backend.fork(context.git_repo_owner, context.git_repo_name)\n  File \"/home/runner/micromamba/envs/cf-scripts/lib/python3.11/contextlib.py\", line 81, in inner\n    return func(*args, **kwds)\n           ^^^^^^^^^^^^^^^^^^^\n  File \"/home/runner/work/cf-scripts/cf-scripts/cf-scripts/conda_forge_tick/git_utils.py\", line 844, in fork\n    if self.does_repository_exist(self.user, repo_name):\n                                  ^^^^^^^^^\n  File \"/home/runner/micromamba/envs/cf-scripts/lib/python3.11/functools.py\", line 1001, in __get__\n    val = self.func(instance)\n          ^^^^^^^^^^^^^^^^^^^\n  File \"/home/runner/work/cf-scripts/cf-scripts/cf-scripts/conda_forge_tick/git_utils.py\", line 878, in user\n    return self.pygithub_client.get_user().login\n           ^^^^^^^^^^^^^^^^^^^^^^^^^^^^^^^^^^^^^\n  File \"/home/runner/micromamba/envs/cf-scripts/lib/python3.11/site-packages/github/AuthenticatedUser.py\", line 281, in login\n    self._completeIfNotSet(self._login)\n  File \"/home/runner/micromamba/envs/cf-scripts/lib/python3.11/site-packages/github/GithubObject.py\", line 499, in _completeIfNotSet\n    self._completeIfNeeded()\n  File \"/home/runner/micromamba/envs/cf-scripts/lib/python3.11/site-packages/github/GithubObject.py\", line 503, in _completeIfNeeded\n    self.__complete()\n  File \"/home/runner/micromamba/envs/cf-scripts/lib/python3.11/site-packages/github/GithubObject.py\", line 508, in __complete\n    headers, data = self._requester.requestJsonAndCheck(\"GET\", self._url.value)\n                    ^^^^^^^^^^^^^^^^^^^^^^^^^^^^^^^^^^^^^^^^^^^^^^^^^^^^^^^^^^^\n  File \"/home/runner/micromamba/envs/cf-scripts/lib/python3.11/site-packages/github/Requester.py\", line 586, in requestJsonAndCheck\n    return self.__check(*self.requestJson(verb, url, parameters, headers, input, self.__customConnection(url)))\n                         ^^^^^^^^^^^^^^^^^^^^^^^^^^^^^^^^^^^^^^^^^^^^^^^^^^^^^^^^^^^^^^^^^^^^^^^^^^^^^^^^^^^^^\n  File \"/home/runner/micromamba/envs/cf-scripts/lib/python3.11/site-packages/github/Requester.py\", line 856, in requestJson\n    return self.__requestEncode(cnx, verb, url, parameters, headers, input, encode)\n           ^^^^^^^^^^^^^^^^^^^^^^^^^^^^^^^^^^^^^^^^^^^^^^^^^^^^^^^^^^^^^^^^^^^^^^^^\n  File \"/home/runner/micromamba/envs/cf-scripts/lib/python3.11/site-packages/github/Requester.py\", line 977, in __requestEncode\n    status, responseHeaders, output = self.__requestRaw(cnx, verb, url, requestHeaders, encoded_input)\n                                      ^^^^^^^^^^^^^^^^^^^^^^^^^^^^^^^^^^^^^^^^^^^^^^^^^^^^^^^^^^^^^^^^\n  File \"/home/runner/micromamba/envs/cf-scripts/lib/python3.11/site-packages/github/Requester.py\", line 1011, in __requestRaw\n    response = cnx.getresponse()\n               ^^^^^^^^^^^^^^^^^\n  File \"/home/runner/micromamba/envs/cf-scripts/lib/python3.11/site-packages/github/Requester.py\", line 202, in getresponse\n    r = verb(\n        ^^^^^\n  File \"/home/runner/micromamba/envs/cf-scripts/lib/python3.11/site-packages/requests/sessions.py\", line 602, in get\n    return self.request(\"GET\", url, **kwargs)\n           ^^^^^^^^^^^^^^^^^^^^^^^^^^^^^^^^^^\n  File \"/home/runner/micromamba/envs/cf-scripts/lib/python3.11/site-packages/requests/sessions.py\", line 589, in request\n    resp = self.send(prep, **send_kwargs)\n           ^^^^^^^^^^^^^^^^^^^^^^^^^^^^^^\n  File \"/home/runner/micromamba/envs/cf-scripts/lib/python3.11/site-packages/requests/sessions.py\", line 703, in send\n    r = adapter.send(request, **kwargs)\n        ^^^^^^^^^^^^^^^^^^^^^^^^^^^^^^^\n  File \"/home/runner/micromamba/envs/cf-scripts/lib/python3.11/site-packages/requests/adapters.py\", line 691, in send\n    raise RetryError(e, request=request)\nrequests.exceptions.RetryError: HTTPSConnectionPool(host='api.github.com', port=443): Max retries exceeded with url: /user (Caused by ResponseError('too many 502 error responses'))\n"
 }
}