{
 "PRed": [
  {
   "PR": {
    "labels": [],
    "number": 1,
    "state": "closed"
   },
   "data": {
    "bot_rerun": false,
    "migrator_name": "Version",
    "migrator_version": 0,
    "version": "1.1.2"
   },
   "keys": [
    "bot_rerun",
    "migrator_name",
    "migrator_version",
    "version"
   ]
  },
  {
   "PR": {
    "labels": [],
    "number": 5,
    "state": "closed"
   },
   "data": {
    "bot_rerun": false,
    "migrator_name": "Version",
    "migrator_version": 0,
    "version": "1.1.3"
   },
   "keys": [
    "bot_rerun",
    "migrator_name",
    "migrator_version",
    "version"
   ]
  },
  {
   "PR": {
    "labels": [],
    "number": 6,
    "state": "closed"
   },
   "data": {
    "bot_rerun": false,
    "migrator_name": "Version",
    "migrator_version": 0,
    "version": "1.1.4"
   },
   "keys": [
    "bot_rerun",
    "migrator_name",
    "migrator_version",
    "version"
   ]
  },
  {
   "PR": {
    "labels": [],
    "number": 8,
    "state": "closed"
   },
   "data": {
    "bot_rerun": false,
    "migrator_name": "Version",
    "migrator_version": 0,
    "version": "1.1.5"
   },
   "keys": [
    "bot_rerun",
    "migrator_name",
    "migrator_version",
    "version"
   ]
  },
  {
   "PR": {
    "labels": [],
    "number": 9,
    "state": "closed"
   },
   "data": {
    "bot_rerun": false,
    "migrator_name": "Version",
    "migrator_version": 0,
    "version": "1.1.7"
   },
   "keys": [
    "bot_rerun",
    "migrator_name",
    "migrator_version",
    "version"
   ]
  },
  {
   "PR": {
    "labels": [],
    "number": 10,
    "state": "closed"
   },
   "data": {
    "bot_rerun": false,
    "migrator_name": "Version",
    "migrator_version": 0,
    "version": "1.1.8"
   },
   "keys": [
    "bot_rerun",
    "migrator_name",
    "migrator_version",
    "version"
   ]
  },
  {
   "PR": {
    "labels": [],
    "number": 11,
    "state": "closed"
   },
   "data": {
    "bot_rerun": false,
    "migrator_name": "Version",
    "migrator_version": 0,
    "version": "1.1.9"
   },
   "keys": [
    "bot_rerun",
    "migrator_name",
    "migrator_version",
    "version"
   ]
  },
  {
   "PR": {
    "labels": [],
    "number": 12,
    "state": "closed"
   },
   "data": {
    "bot_rerun": false,
    "migrator_name": "Version",
    "migrator_version": 0,
    "version": "1.1.10"
   },
   "keys": [
    "bot_rerun",
    "migrator_name",
    "migrator_version",
    "version"
   ]
  },
  {
   "PR": {
    "labels": [],
    "number": 13,
    "state": "closed"
   },
   "data": {
    "bot_rerun": false,
    "migrator_name": "Version",
    "migrator_version": 0,
    "version": "1.1.11"
   },
   "keys": [
    "bot_rerun",
    "migrator_name",
    "migrator_version",
    "version"
   ]
  },
  {
   "PR": {
    "labels": [],
    "number": 14,
    "state": "closed"
   },
   "data": {
    "bot_rerun": false,
    "migrator_name": "Version",
    "migrator_version": 0,
    "version": "1.2.4"
   },
   "keys": [
    "bot_rerun",
    "migrator_name",
    "migrator_version",
    "version"
   ]
  },
  {
   "PR": {
    "__lazy_json__": "pr_json/2225028634.json"
   },
   "data": {
    "bot_rerun": false,
    "migrator_name": "Version",
    "migrator_version": 0,
    "version": "1.2.5"
   },
   "keys": [
    "bot_rerun",
    "migrator_name",
    "migrator_version",
    "version"
   ]
  }
 ],
 "bad": false,
 "pinning_version": "2024.12.09.22.31.18",
 "pre_pr_migrator_attempts": {
  "noarch_python_min": 7
 },
 "pre_pr_migrator_status": {
  "noarch_python_min": "bot error (<a href=\"https://github.com/regro/cf-scripts/actions/runs/12978392951\">bot CI job</a>): main:\nTraceback (most recent call last):\n  File \"/opt/conda/envs/cf-scripts/lib/python3.11/site-packages/conda_forge_feedstock_ops/__main__.py\", line 104, in _run_bot_task\n    data = func(**kwargs)\n           ^^^^^^^^^^^^^^\n  File \"/opt/conda/envs/cf-scripts/lib/python3.11/site-packages/conda_forge_feedstock_ops/__main__.py\", line 216, in _rerender_feedstock\n    msg = rerender_local(fs_dir, **kwargs)\n          ^^^^^^^^^^^^^^^^^^^^^^^^^^^^^^^^\n  File \"/opt/conda/envs/cf-scripts/lib/python3.11/site-packages/conda_forge_feedstock_ops/rerender.py\", line 255, in rerender_local\n    raise RuntimeError(f\"Failed to rerender.\noutput: {ret.stdout}\n\")\nRuntimeError: Failed to rerender.\noutput: Traceback (most recent call last):\n  File \"/opt/conda/envs/cf-scripts/lib/python3.11/site-packages/urllib3/connectionpool.py\", line 715, in urlopen\n    httplib_response = self._make_request(\n                       ^^^^^^^^^^^^^^^^^^^\n  File \"/opt/conda/envs/cf-scripts/lib/python3.11/site-packages/urllib3/connectionpool.py\", line 467, in _make_request\n    six.raise_from(e, None)\n  File \"<string>\", line 3, in raise_from\n  File \"/opt/conda/envs/cf-scripts/lib/python3.11/site-packages/urllib3/connectionpool.py\", line 462, in _make_request\n    httplib_response = conn.getresponse()\n                       ^^^^^^^^^^^^^^^^^^\n  File \"/opt/conda/envs/cf-scripts/lib/python3.11/http/client.py\", line 1395, in getresponse\n    response.begin()\n  File \"/opt/conda/envs/cf-scripts/lib/python3.11/http/client.py\", line 325, in begin\n    version, status, reason = self._read_status()\n                              ^^^^^^^^^^^^^^^^^^^\n  File \"/opt/conda/envs/cf-scripts/lib/python3.11/http/client.py\", line 294, in _read_status\n    raise RemoteDisconnected(\"Remote end closed connection without\"\nhttp.client.RemoteDisconnected: Remote end closed connection without response\n\nDuring handling of the above exception, another exception occurred:\n\nTraceback (most recent call last):\n  File \"/opt/conda/envs/cf-scripts/lib/python3.11/site-packages/requests/adapters.py\", line 667, in send\n    resp = conn.urlopen(\n           ^^^^^^^^^^^^^\n  File \"/opt/conda/envs/cf-scripts/lib/python3.11/site-packages/urllib3/connectionpool.py\", line 801, in urlopen\n    retries = retries.increment(\n              ^^^^^^^^^^^^^^^^^^\n  File \"/opt/conda/envs/cf-scripts/lib/python3.11/site-packages/urllib3/util/retry.py\", line 552, in increment\n    raise six.reraise(type(error), error, _stacktrace)\n          ^^^^^^^^^^^^^^^^^^^^^^^^^^^^^^^^^^^^^^^^^^^^\n  File \"/opt/conda/envs/cf-scripts/lib/python3.11/site-packages/urllib3/packages/six.py\", line 769, in reraise\n    raise value.with_traceback(tb)\n  File \"/opt/conda/envs/cf-scripts/lib/python3.11/site-packages/urllib3/connectionpool.py\", line 715, in urlopen\n    httplib_response = self._make_request(\n                       ^^^^^^^^^^^^^^^^^^^\n  File \"/opt/conda/envs/cf-scripts/lib/python3.11/site-packages/urllib3/connectionpool.py\", line 467, in _make_request\n    six.raise_from(e, None)\n  File \"<string>\", line 3, in raise_from\n  File \"/opt/conda/envs/cf-scripts/lib/python3.11/site-packages/urllib3/connectionpool.py\", line 462, in _make_request\n    httplib_response = conn.getresponse()\n                       ^^^^^^^^^^^^^^^^^^\n  File \"/opt/conda/envs/cf-scripts/lib/python3.11/http/client.py\", line 1395, in getresponse\n    response.begin()\n  File \"/opt/conda/envs/cf-scripts/lib/python3.11/http/client.py\", line 325, in begin\n    version, status, reason = self._read_status()\n                              ^^^^^^^^^^^^^^^^^^^\n  File \"/opt/conda/envs/cf-scripts/lib/python3.11/http/client.py\", line 294, in _read_status\n    raise RemoteDisconnected(\"Remote end closed connection without\"\nurllib3.exceptions.ProtocolError: ('Connection aborted.', RemoteDisconnected('Remote end closed connection without response'))\n\nDuring handling of the above exception, another exception occurred:\n\nTraceback (most recent call last):\n  File \"/opt/conda/envs/cf-scripts/bin/conda-smithy\", line 10, in <module>\n    sys.exit(main())\n             ^^^^^^\n  File \"/opt/conda/envs/cf-scripts/lib/python3.11/site-packages/conda_smithy/cli.py\", line 767, in main\n    args.subcommand_func(args)\n  File \"/opt/conda/envs/cf-scripts/lib/python3.11/site-packages/conda_smithy/cli.py\", line 610, in __call__\n    self._call(args, args.temporary_directory)\n  File \"/opt/conda/envs/cf-scripts/lib/python3.11/site-packages/conda_smithy/cli.py\", line 613, in _call\n    configure_feedstock.main(\n  File \"/opt/conda/envs/cf-scripts/lib/python3.11/site-packages/conda_smithy/configure_feedstock.py\", line 2858, in main\n    exclusive_config_file, cf_pinning_ver = get_cached_cfp_file_path(\n                                            ^^^^^^^^^^^^^^^^^^^^^^^^^\n  File \"/opt/conda/envs/cf-scripts/lib/python3.11/site-packages/conda_smithy/configure_feedstock.py\", line 2671, in get_cached_cfp_file_path\n    current_pinning_version = get_most_recent_version(\n                              ^^^^^^^^^^^^^^^^^^^^^^^^\n  File \"/opt/conda/envs/cf-scripts/lib/python3.11/site-packages/conda_smithy/configure_feedstock.py\", line 2541, in get_most_recent_version\n    request = requests.get(\n              ^^^^^^^^^^^^^\n  File \"/opt/conda/envs/cf-scripts/lib/python3.11/site-packages/requests/api.py\", line 73, in get\n    return request(\"get\", url, params=params, **kwargs)\n           ^^^^^^^^^^^^^^^^^^^^^^^^^^^^^^^^^^^^^^^^^^^^\n  File \"/opt/conda/envs/cf-scripts/lib/python3.11/site-packages/requests/api.py\", line 59, in request\n    return session.request(method=method, url=url, **kwargs)\n           ^^^^^^^^^^^^^^^^^^^^^^^^^^^^^^^^^^^^^^^^^^^^^^^^^\n  File \"/opt/conda/envs/cf-scripts/lib/python3.11/site-packages/requests/sessions.py\", line 589, in request\n    resp = self.send(prep, **send_kwargs)\n           ^^^^^^^^^^^^^^^^^^^^^^^^^^^^^^\n  File \"/opt/conda/envs/cf-scripts/lib/python3.11/site-packages/requests/sessions.py\", line 703, in send\n    r = adapter.send(request, **kwargs)\n        ^^^^^^^^^^^^^^^^^^^^^^^^^^^^^^^\n  File \"/opt/conda/envs/cf-scripts/lib/python3.11/site-packages/requests/adapters.py\", line 682, in send\n    raise ConnectionError(err, request=request)\nrequests.exceptions.ConnectionError: ('Connection aborted.', RemoteDisconnected('Remote end closed connection without response'))\n\n\n"
 },
 "smithy_version": "3.44.9"
}