{
 "PRed": [
  {
   "PR": {
    "number": 1,
    "state": "closed"
   },
   "data": {
    "bot_rerun": false,
    "migrator_name": "Version",
    "migrator_version": 0,
    "version": "1.3.2"
   },
   "keys": [
    "bot_rerun",
    "migrator_name",
    "migrator_version",
    "version"
   ]
  },
  {
   "PR": {
    "number": 2,
    "state": "closed"
   },
   "data": {
    "bot_rerun": false,
    "migrator_name": "Version",
    "migrator_version": 0,
    "version": "1.3.3"
   },
   "keys": [
    "bot_rerun",
    "migrator_name",
    "migrator_version",
    "version"
   ]
  },
  {
   "PR": {
    "number": 3,
    "state": "closed"
   },
   "data": {
    "bot_rerun": false,
    "migrator_name": "Version",
    "migrator_version": 0,
    "version": "1.4.1"
   },
   "keys": [
    "bot_rerun",
    "migrator_name",
    "migrator_version",
    "version"
   ]
  },
  {
   "PR": {
    "number": 4,
    "state": "closed"
   },
   "data": {
    "bot_rerun": false,
    "migrator_name": "Version",
    "migrator_version": 0,
    "version": "1.4.2"
   },
   "keys": [
    "bot_rerun",
    "migrator_name",
    "migrator_version",
    "version"
   ]
  },
  {
   "PR": {
    "labels": [],
    "number": 5,
    "state": "closed"
   },
   "data": {
    "bot_rerun": false,
    "migrator_name": "NoarchPythonMinMigrator",
    "migrator_version": 1,
    "name": "noarch_python_min"
   },
   "keys": [
    "bot_rerun",
    "migrator_name",
    "migrator_version",
    "name"
   ]
  }
 ],
 "bad": {
  "exception": "Error running 'conda-forge-tick-container migrate-feedstock --feedstock-name syntok --default-branch main --existing-feedstock-node-attrs - --log-level info --kwargs {\n \"hash_type\": \"sha256\"\n}' in container - error ConnectionError raised:\nProtocolError('Connection aborted.', RemoteDisconnected('Remote end closed connection without response'))",
  "traceback": [
   "Traceback (most recent call last):",
   "  File \"/opt/conda/envs/cf-scripts/lib/python3.11/site-packages/urllib3/connectionpool.py\", line 715, in urlopen",
   "    httplib_response = self._make_request(",
   "                       ^^^^^^^^^^^^^^^^^^^",
   "  File \"/opt/conda/envs/cf-scripts/lib/python3.11/site-packages/urllib3/connectionpool.py\", line 467, in _make_request",
   "    six.raise_from(e, None)",
   "  File \"<string>\", line 3, in raise_from",
   "  File \"/opt/conda/envs/cf-scripts/lib/python3.11/site-packages/urllib3/connectionpool.py\", line 462, in _make_request",
   "    httplib_response = conn.getresponse()",
   "                       ^^^^^^^^^^^^^^^^^^",
   "  File \"/opt/conda/envs/cf-scripts/lib/python3.11/http/client.py\", line 1395, in getresponse",
   "    response.begin()",
   "  File \"/opt/conda/envs/cf-scripts/lib/python3.11/http/client.py\", line 325, in begin",
   "    version, status, reason = self._read_status()",
   "                              ^^^^^^^^^^^^^^^^^^^",
   "  File \"/opt/conda/envs/cf-scripts/lib/python3.11/http/client.py\", line 294, in _read_status",
   "    raise RemoteDisconnected(\"Remote end closed connection without\"",
   "http.client.RemoteDisconnected: Remote end closed connection without response",
   "",
   "During handling of the above exception, another exception occurred:",
   "",
   "Traceback (most recent call last):",
   "  File \"/opt/conda/envs/cf-scripts/lib/python3.11/site-packages/requests/adapters.py\", line 667, in send",
   "    resp = conn.urlopen(",
   "           ^^^^^^^^^^^^^",
   "  File \"/opt/conda/envs/cf-scripts/lib/python3.11/site-packages/urllib3/connectionpool.py\", line 801, in urlopen",
   "    retries = retries.increment(",
   "              ^^^^^^^^^^^^^^^^^^",
   "  File \"/opt/conda/envs/cf-scripts/lib/python3.11/site-packages/urllib3/util/retry.py\", line 552, in increment",
   "    raise six.reraise(type(error), error, _stacktrace)",
   "          ^^^^^^^^^^^^^^^^^^^^^^^^^^^^^^^^^^^^^^^^^^^^",
   "  File \"/opt/conda/envs/cf-scripts/lib/python3.11/site-packages/urllib3/packages/six.py\", line 769, in reraise",
   "    raise value.with_traceback(tb)",
   "  File \"/opt/conda/envs/cf-scripts/lib/python3.11/site-packages/urllib3/connectionpool.py\", line 715, in urlopen",
   "    httplib_response = self._make_request(",
   "                       ^^^^^^^^^^^^^^^^^^^",
   "  File \"/opt/conda/envs/cf-scripts/lib/python3.11/site-packages/urllib3/connectionpool.py\", line 467, in _make_request",
   "    six.raise_from(e, None)",
   "  File \"<string>\", line 3, in raise_from",
   "  File \"/opt/conda/envs/cf-scripts/lib/python3.11/site-packages/urllib3/connectionpool.py\", line 462, in _make_request",
   "    httplib_response = conn.getresponse()",
   "                       ^^^^^^^^^^^^^^^^^^",
   "  File \"/opt/conda/envs/cf-scripts/lib/python3.11/http/client.py\", line 1395, in getresponse",
   "    response.begin()",
   "  File \"/opt/conda/envs/cf-scripts/lib/python3.11/http/client.py\", line 325, in begin",
   "    version, status, reason = self._read_status()",
   "                              ^^^^^^^^^^^^^^^^^^^",
   "  File \"/opt/conda/envs/cf-scripts/lib/python3.11/http/client.py\", line 294, in _read_status",
   "    raise RemoteDisconnected(\"Remote end closed connection without\"",
   "urllib3.exceptions.ProtocolError: ('Connection aborted.', RemoteDisconnected('Remote end closed connection without response'))",
   "",
   "During handling of the above exception, another exception occurred:",
   "",
   "Traceback (most recent call last):",
   "  File \"/opt/autotick-bot/conda_forge_tick/container_cli.py\", line 119, in _run_bot_task",
   "    data = func(attrs=attrs, **kwargs)",
   "           ^^^^^^^^^^^^^^^^^^^^^^^^^^^",
   "  File \"/opt/autotick-bot/conda_forge_tick/container_cli.py\", line 197, in _migrate_feedstock",
   "    from conda_forge_tick.migrators import make_from_lazy_json_data",
   "  File \"/opt/autotick-bot/conda_forge_tick/migrators/__init__.py\", line 24, in <module>",
   "    from .dep_updates import DependencyUpdateMigrator",
   "  File \"/opt/autotick-bot/conda_forge_tick/migrators/dep_updates.py\", line 6, in <module>",
   "    from conda_forge_tick.update_deps import apply_dep_update, get_dep_updates_and_hints",
   "  File \"/opt/autotick-bot/conda_forge_tick/update_deps.py\", line 68, in <module>",
   "    r = requests.get(",
   "        ^^^^^^^^^^^^^",
   "  File \"/opt/conda/envs/cf-scripts/lib/python3.11/site-packages/requests/api.py\", line 73, in get",
   "    return request(\"get\", url, params=params, **kwargs)",
   "           ^^^^^^^^^^^^^^^^^^^^^^^^^^^^^^^^^^^^^^^^^^^^",
   "  File \"/opt/conda/envs/cf-scripts/lib/python3.11/site-packages/requests/api.py\", line 59, in request",
   "    return session.request(method=method, url=url, **kwargs)",
   "           ^^^^^^^^^^^^^^^^^^^^^^^^^^^^^^^^^^^^^^^^^^^^^^^^^",
   "  File \"/opt/conda/envs/cf-scripts/lib/python3.11/site-packages/requests/sessions.py\", line 589, in request",
   "    resp = self.send(prep, **send_kwargs)",
   "           ^^^^^^^^^^^^^^^^^^^^^^^^^^^^^^",
   "  File \"/opt/conda/envs/cf-scripts/lib/python3.11/site-packages/requests/sessions.py\", line 703, in send",
   "    r = adapter.send(request, **kwargs)",
   "        ^^^^^^^^^^^^^^^^^^^^^^^^^^^^^^^",
   "  File \"/opt/conda/envs/cf-scripts/lib/python3.11/site-packages/requests/adapters.py\", line 682, in send",
   "    raise ConnectionError(err, request=request)",
   "requests.exceptions.ConnectionError: ('Connection aborted.', RemoteDisconnected('Remote end closed connection without response'))",
   ""
  ]
 },
 "pinning_version": "2025.01.11.16.15.44",
 "pre_pr_migrator_attempts": {
  "version": 1
 },
 "pre_pr_migrator_status": {
  "version": "bot error (<a href=\"https://github.com/regro/autotick-bot/actions/runs/1974308377\">bot CI job</a>): master: Traceback (most recent call last):\n  File \"/home/runner/work/autotick-bot/autotick-bot/cf-scripts/conda_forge_tick/git_utils.py\", line 223, in fetch_repo\n    _run_git_cmd(f\"git checkout --track upstream/{base_branch} {quiet}\")\n  File \"/home/runner/work/autotick-bot/autotick-bot/cf-scripts/conda_forge_tick/git_utils.py\", line 198, in _run_git_cmd\n    return subprocess.run(cmd, shell=True, check=True)\n  File \"/usr/share/miniconda3/envs/run_env/lib/python3.9/subprocess.py\", line 528, in run\n    raise CalledProcessError(retcode, process.args,\nsubprocess.CalledProcessError: Command 'git checkout --track upstream/master --quiet' returned non-zero exit status 128.\n\nDuring handling of the above exception, another exception occurred:\n\nTraceback (most recent call last):\n  File \"/home/runner/work/autotick-bot/autotick-bot/cf-scripts/conda_forge_tick/auto_tick.py\", line 1135, in _run_migrator\n    migrator_uid, pr_json = run(\n  File \"/home/runner/work/autotick-bot/autotick-bot/cf-scripts/conda_forge_tick/auto_tick.py\", line 202, in run\n    feedstock_dir, repo = get_repo(\n  File \"/home/runner/work/autotick-bot/autotick-bot/cf-scripts/conda_forge_tick/git_utils.py\", line 313, in get_repo\n    if fetch_repo(\n  File \"/home/runner/work/autotick-bot/autotick-bot/cf-scripts/conda_forge_tick/git_utils.py\", line 225, in fetch_repo\n    _run_git_cmd(\n  File \"/home/runner/work/autotick-bot/autotick-bot/cf-scripts/conda_forge_tick/git_utils.py\", line 198, in _run_git_cmd\n    return subprocess.run(cmd, shell=True, check=True)\n  File \"/usr/share/miniconda3/envs/run_env/lib/python3.9/subprocess.py\", line 528, in run\n    raise CalledProcessError(retcode, process.args,\nsubprocess.CalledProcessError: Command 'git checkout -b master upstream/master --quiet' returned non-zero exit status 128.\n"
 },
 "smithy_version": "3.45.1"
}