{
 "bad": false,
 "new_version": "1.20.2",
 "new_version_attempts": {
  "1.10.0": 1,
  "1.11.0": 2,
  "1.11.1": 1,
  "1.12.0": 2,
  "1.12.1": 1,
  "1.13.1": 1,
  "1.14.0": 1,
  "1.14.1": 1,
  "1.15.0": 1,
  "1.15.1": 1,
  "1.16.0": 1,
  "1.16.1": 1,
  "1.16.2": 1,
  "1.16.3": 1,
  "1.17.0": 1,
  "1.17.1": 1,
  "1.17.3": 1,
  "1.20.2": 1,
  "1.8.0": 44,
  "1.8.1": 57,
  "1.8.2": 10,
  "1.9.0": 3,
  "1.9.1": 1
 },
 "new_version_errors": {
  "1.12.0": "The recipe did not change in the version migration, a URL did not hash, or there is jinja2 syntax the bot cannot handle!\n\nPlease check the URLs in your recipe with version '1.12.0' to make sure they exist!\n\nWe also found the following errors:\n\n - could not hash URL template 'https://github.com/nlohmann/json/archive/refs/tags/v3.9.1.tar.gz'\n - could not hash URL template 'https://github.com/onnx/onnx/archive/850a81b0b77786bf99ea90580242b084f86a6235.tar.gz'\n - could not hash URL template 'https://github.com/pytorch/cpuinfo/archive/5916273f79a21551890fd3d56fc5375a78d1598d.zip'\n - could not hash URL template 'https://github.com/microsoft/onnxruntime/archive/refs/tags/v{{ version }}.tar.gz'\n",
  "1.20.2": "bot error (<a href=\"https://github.com/regro/cf-scripts/actions/runs/13271266784\">bot CI job</a>): main:\nTraceback (most recent call last):\n  File \"/home/runner/micromamba/envs/cf-scripts/lib/python3.11/site-packages/urllib3/connectionpool.py\", line 467, in _make_request\n    six.raise_from(e, None)\n  File \"<string>\", line 3, in raise_from\n  File \"/home/runner/micromamba/envs/cf-scripts/lib/python3.11/site-packages/urllib3/connectionpool.py\", line 462, in _make_request\n    httplib_response = conn.getresponse()\n                       ^^^^^^^^^^^^^^^^^^\n  File \"/home/runner/micromamba/envs/cf-scripts/lib/python3.11/http/client.py\", line 1395, in getresponse\n    response.begin()\n  File \"/home/runner/micromamba/envs/cf-scripts/lib/python3.11/http/client.py\", line 325, in begin\n    version, status, reason = self._read_status()\n                              ^^^^^^^^^^^^^^^^^^^\n  File \"/home/runner/micromamba/envs/cf-scripts/lib/python3.11/http/client.py\", line 286, in _read_status\n    line = str(self.fp.readline(_MAXLINE + 1), \"iso-8859-1\")\n               ^^^^^^^^^^^^^^^^^^^^^^^^^^^^^^\n  File \"/home/runner/micromamba/envs/cf-scripts/lib/python3.11/socket.py\", line 718, in readinto\n    return self._sock.recv_into(b)\n           ^^^^^^^^^^^^^^^^^^^^^^^\n  File \"/home/runner/micromamba/envs/cf-scripts/lib/python3.11/ssl.py\", line 1314, in recv_into\n    return self.read(nbytes, buffer)\n           ^^^^^^^^^^^^^^^^^^^^^^^^^\n  File \"/home/runner/micromamba/envs/cf-scripts/lib/python3.11/ssl.py\", line 1166, in read\n    return self._sslobj.read(len, buffer)\n           ^^^^^^^^^^^^^^^^^^^^^^^^^^^^^^\nTimeoutError: The read operation timed out\n\nDuring handling of the above exception, another exception occurred:\n\nTraceback (most recent call last):\n  File \"/home/runner/micromamba/envs/cf-scripts/lib/python3.11/site-packages/requests/adapters.py\", line 667, in send\n    resp = conn.urlopen(\n           ^^^^^^^^^^^^^\n  File \"/home/runner/micromamba/envs/cf-scripts/lib/python3.11/site-packages/urllib3/connectionpool.py\", line 801, in urlopen\n    retries = retries.increment(\n              ^^^^^^^^^^^^^^^^^^\n  File \"/home/runner/micromamba/envs/cf-scripts/lib/python3.11/site-packages/urllib3/util/retry.py\", line 552, in increment\n    raise six.reraise(type(error), error, _stacktrace)\n          ^^^^^^^^^^^^^^^^^^^^^^^^^^^^^^^^^^^^^^^^^^^^\n  File \"/home/runner/micromamba/envs/cf-scripts/lib/python3.11/site-packages/urllib3/packages/six.py\", line 770, in reraise\n    raise value\n  File \"/home/runner/micromamba/envs/cf-scripts/lib/python3.11/site-packages/urllib3/connectionpool.py\", line 715, in urlopen\n    httplib_response = self._make_request(\n                       ^^^^^^^^^^^^^^^^^^^\n  File \"/home/runner/micromamba/envs/cf-scripts/lib/python3.11/site-packages/urllib3/connectionpool.py\", line 469, in _make_request\n    self._raise_timeout(err=e, url=url, timeout_value=read_timeout)\n  File \"/home/runner/micromamba/envs/cf-scripts/lib/python3.11/site-packages/urllib3/connectionpool.py\", line 358, in _raise_timeout\n    raise ReadTimeoutError(\nurllib3.exceptions.ReadTimeoutError: HTTPSConnectionPool(host='api.github.com', port=443): Read timed out. (read timeout=10)\n\nDuring handling of the above exception, another exception occurred:\n\nTraceback (most recent call last):\n  File \"/home/runner/micromamba/envs/cf-scripts/lib/python3.11/site-packages/github3/models.py\", line 201, in _request\n    return request_method(*args, **kwargs)\n           ^^^^^^^^^^^^^^^^^^^^^^^^^^^^^^^\n  File \"/home/runner/work/cf-scripts/cf-scripts/cf-scripts/conda_forge_tick/git_utils.py\", line 751, in post\n    return self._forward_request(self._session.post, *args, **kwargs)\n           ^^^^^^^^^^^^^^^^^^^^^^^^^^^^^^^^^^^^^^^^^^^^^^^^^^^^^^^^^^\n  File \"/home/runner/work/cf-scripts/cf-scripts/cf-scripts/conda_forge_tick/git_utils.py\", line 746, in _forward_request\n    response = method(*args, **kwargs)\n               ^^^^^^^^^^^^^^^^^^^^^^^\n  File \"/home/runner/micromamba/envs/cf-scripts/lib/python3.11/site-packages/requests/sessions.py\", line 637, in post\n    return self.request(\"POST\", url, data=data, json=json, **kwargs)\n           ^^^^^^^^^^^^^^^^^^^^^^^^^^^^^^^^^^^^^^^^^^^^^^^^^^^^^^^^^\n  File \"/home/runner/micromamba/envs/cf-scripts/lib/python3.11/site-packages/github3/session.py\", line 171, in request\n    response = super().request(*args, **kwargs)\n               ^^^^^^^^^^^^^^^^^^^^^^^^^^^^^^^^\n  File \"/home/runner/micromamba/envs/cf-scripts/lib/python3.11/site-packages/requests/sessions.py\", line 589, in request\n    resp = self.send(prep, **send_kwargs)\n           ^^^^^^^^^^^^^^^^^^^^^^^^^^^^^^\n  File \"/home/runner/micromamba/envs/cf-scripts/lib/python3.11/site-packages/requests/sessions.py\", line 703, in send\n    r = adapter.send(request, **kwargs)\n        ^^^^^^^^^^^^^^^^^^^^^^^^^^^^^^^\n  File \"/home/runner/micromamba/envs/cf-scripts/lib/python3.11/site-packages/requests/adapters.py\", line 713, in send\n    raise ReadTimeout(e, request=request)\nrequests.exceptions.ReadTimeout: HTTPSConnectionPool(host='api.github.com', port=443): Read timed out. (read timeout=10)\n\nDuring handling of the above exception, another exception occurred:\n\nTraceback (most recent call last):\n  File \"/home/runner/work/cf-scripts/cf-scripts/cf-scripts/conda_forge_tick/auto_tick.py\", line 744, in _run_migrator_on_feedstock_branch\n    migrator_uid, pr_json = run_with_tmpdir(\n                            ^^^^^^^^^^^^^^^^\n  File \"/home/runner/work/cf-scripts/cf-scripts/cf-scripts/conda_forge_tick/auto_tick.py\", line 451, in run_with_tmpdir\n    return run(\n           ^^^^\n  File \"/home/runner/work/cf-scripts/cf-scripts/cf-scripts/conda_forge_tick/auto_tick.py\", line 626, in run\n    pr_data = git_backend.create_pull_request(\n              ^^^^^^^^^^^^^^^^^^^^^^^^^^^^^^^^\n  File \"/home/runner/work/cf-scripts/cf-scripts/cf-scripts/conda_forge_tick/git_utils.py\", line 928, in create_pull_request\n    response: github3.pulls.ShortPullRequest | None = repo.create_pull(\n                                                      ^^^^^^^^^^^^^^^^^\n  File \"/home/runner/micromamba/envs/cf-scripts/lib/python3.11/site-packages/github3/decorators.py\", line 24, in auth_wrapper\n    return func(self, *args, **kwargs)\n           ^^^^^^^^^^^^^^^^^^^^^^^^^^^\n  File \"/home/runner/micromamba/envs/cf-scripts/lib/python3.11/site-packages/github3/repos/repo.py\", line 1185, in create_pull\n    return self._create_pull(data)\n           ^^^^^^^^^^^^^^^^^^^^^^^\n  File \"/home/runner/micromamba/envs/cf-scripts/lib/python3.11/site-packages/github3/repos/repo.py\", line 117, in _create_pull\n    json = self._json(self._post(url, data=data), 201)\n                      ^^^^^^^^^^^^^^^^^^^^^^^^^^\n  File \"/home/runner/micromamba/envs/cf-scripts/lib/python3.11/site-packages/github3/models.py\", line 226, in _post\n    return self._request(\"post\", url, data, **kwargs)\n           ^^^^^^^^^^^^^^^^^^^^^^^^^^^^^^^^^^^^^^^^^^\n  File \"/home/runner/micromamba/envs/cf-scripts/lib/python3.11/site-packages/github3/models.py\", line 206, in _request\n    raise exceptions.ConnectionError(exc)\ngithub3.exceptions.ConnectionError: <class 'requests.exceptions.ReadTimeout'>: A connection-level exception occurred: HTTPSConnectionPool(host='api.github.com', port=443): Read timed out. (read timeout=10)\n",
  "1.8.0": "The recipe did not change in the version migration, a URL did not hash, or there is jinja2 syntax the bot cannot handle!\n\nPlease check the URLs in your recipe with version '1.8.0' to make sure they exist!\n\nWe also found the following errors:\n\n - recipe did not appear to change even though the bot said it should have\n",
  "1.8.1": "The recipe did not change in the version migration, a URL did not hash, or there is jinja2 syntax the bot cannot handle!\n\nPlease check the URLs in your recipe with version '1.8.1' to make sure they exist!\n\nWe also found the following errors:\n\n - recipe did not appear to change even though the bot said it should have\n",
  "1.8.2": "The recipe did not change in the version migration, a URL did not hash, or there is jinja2 syntax the bot cannot handle!\n\nPlease check the URLs in your recipe with version '1.8.2' to make sure they exist!\n\nWe also found the following errors:\n\n - recipe did not appear to change even though the bot said it should have\n",
  "1.9.0": "The recipe did not change in the version migration, a URL did not hash, or there is jinja2 syntax the bot cannot handle!\n\nPlease check the URLs in your recipe with version '1.9.0' to make sure they exist!\n\nWe also found the following errors:\n\n - recipe did not appear to change even though the bot said it should have\n"
 }
}