{
 "bad": false,
 "new_version": "25.1.2",
 "new_version_attempts": {
  "25.1.2": 1
 },
 "new_version_errors": {
  "25.1.2": "bot error (<a href=\"https://github.com/regro/cf-scripts/actions/runs/13329213767\">bot CI job</a>): main:\nTraceback (most recent call last):\n  File \"/opt/conda/envs/cf-scripts/lib/python3.11/site-packages/urllib3/connectionpool.py\", line 715, in urlopen\n    httplib_response = self._make_request(\n                       ^^^^^^^^^^^^^^^^^^^\n  File \"/opt/conda/envs/cf-scripts/lib/python3.11/site-packages/urllib3/connectionpool.py\", line 467, in _make_request\n    six.raise_from(e, None)\n  File \"<string>\", line 3, in raise_from\n  File \"/opt/conda/envs/cf-scripts/lib/python3.11/site-packages/urllib3/connectionpool.py\", line 462, in _make_request\n    httplib_response = conn.getresponse()\n                       ^^^^^^^^^^^^^^^^^^\n  File \"/opt/conda/envs/cf-scripts/lib/python3.11/http/client.py\", line 1395, in getresponse\n    response.begin()\n  File \"/opt/conda/envs/cf-scripts/lib/python3.11/http/client.py\", line 325, in begin\n    version, status, reason = self._read_status()\n                              ^^^^^^^^^^^^^^^^^^^\n  File \"/opt/conda/envs/cf-scripts/lib/python3.11/http/client.py\", line 294, in _read_status\n    raise RemoteDisconnected(\"Remote end closed connection without\"\nhttp.client.RemoteDisconnected: Remote end closed connection without response\n\nDuring handling of the above exception, another exception occurred:\n\nTraceback (most recent call last):\n  File \"/opt/conda/envs/cf-scripts/lib/python3.11/site-packages/requests/adapters.py\", line 667, in send\n    resp = conn.urlopen(\n           ^^^^^^^^^^^^^\n  File \"/opt/conda/envs/cf-scripts/lib/python3.11/site-packages/urllib3/connectionpool.py\", line 801, in urlopen\n    retries = retries.increment(\n              ^^^^^^^^^^^^^^^^^^\n  File \"/opt/conda/envs/cf-scripts/lib/python3.11/site-packages/urllib3/util/retry.py\", line 552, in increment\n    raise six.reraise(type(error), error, _stacktrace)\n          ^^^^^^^^^^^^^^^^^^^^^^^^^^^^^^^^^^^^^^^^^^^^\n  File \"/opt/conda/envs/cf-scripts/lib/python3.11/site-packages/urllib3/packages/six.py\", line 769, in reraise\n    raise value.with_traceback(tb)\n  File \"/opt/conda/envs/cf-scripts/lib/python3.11/site-packages/urllib3/connectionpool.py\", line 715, in urlopen\n    httplib_response = self._make_request(\n                       ^^^^^^^^^^^^^^^^^^^\n  File \"/opt/conda/envs/cf-scripts/lib/python3.11/site-packages/urllib3/connectionpool.py\", line 467, in _make_request\n    six.raise_from(e, None)\n  File \"<string>\", line 3, in raise_from\n  File \"/opt/conda/envs/cf-scripts/lib/python3.11/site-packages/urllib3/connectionpool.py\", line 462, in _make_request\n    httplib_response = conn.getresponse()\n                       ^^^^^^^^^^^^^^^^^^\n  File \"/opt/conda/envs/cf-scripts/lib/python3.11/http/client.py\", line 1395, in getresponse\n    response.begin()\n  File \"/opt/conda/envs/cf-scripts/lib/python3.11/http/client.py\", line 325, in begin\n    version, status, reason = self._read_status()\n                              ^^^^^^^^^^^^^^^^^^^\n  File \"/opt/conda/envs/cf-scripts/lib/python3.11/http/client.py\", line 294, in _read_status\n    raise RemoteDisconnected(\"Remote end closed connection without\"\nurllib3.exceptions.ProtocolError: ('Connection aborted.', RemoteDisconnected('Remote end closed connection without response'))\n\nDuring handling of the above exception, another exception occurred:\n\nTraceback (most recent call last):\n  File \"/opt/autotick-bot/conda_forge_tick/container_cli.py\", line 119, in _run_bot_task\n    data = func(attrs=attrs, **kwargs)\n           ^^^^^^^^^^^^^^^^^^^^^^^^^^^\n  File \"/opt/autotick-bot/conda_forge_tick/container_cli.py\", line 225, in _migrate_feedstock\n    data = run_migration_local(\n           ^^^^^^^^^^^^^^^^^^^^\n  File \"/opt/autotick-bot/conda_forge_tick/migration_runner.py\", line 260, in run_migration_local\n    data[\"pr_body\"] = migrator.pr_body(feedstock_ctx)\n                      ^^^^^^^^^^^^^^^^^^^^^^^^^^^^^^^\n  File \"/opt/autotick-bot/conda_forge_tick/migrators/version.py\", line 284, in pr_body\n    for muid in feedstock_ctx.attrs.get(\"pr_info\", {}).get(\"PRed\", [])\n                ^^^^^^^^^^^^^^^^^^^^^^^^^^^^^^^^^^^^^^^^^^^^^^^^^^^^^^\n  File \"<frozen _collections_abc>\", line 774, in get\n  File \"/opt/autotick-bot/conda_forge_tick/lazy_json_backends.py\", line 1052, in __getitem__\n    self._load()\n  File \"/opt/autotick-bot/conda_forge_tick/lazy_json_backends.py\", line 1009, in _load\n    backend.hsetnx(self.hashmap, self.node, dumps({}))\n  File \"/opt/autotick-bot/conda_forge_tick/lazy_json_backends.py\", line 114, in hsetnx\n    if self.hexists(name, key):\n       ^^^^^^^^^^^^^^^^^^^^^^^\n  File \"/opt/autotick-bot/conda_forge_tick/lazy_json_backends.py\", line 256, in hexists\n    status = requests.head(url, allow_redirects=True).status_code\n             ^^^^^^^^^^^^^^^^^^^^^^^^^^^^^^^^^^^^^^^^\n  File \"/opt/conda/envs/cf-scripts/lib/python3.11/site-packages/requests/api.py\", line 100, in head\n    return request(\"head\", url, **kwargs)\n           ^^^^^^^^^^^^^^^^^^^^^^^^^^^^^^\n  File \"/opt/conda/envs/cf-scripts/lib/python3.11/site-packages/requests/api.py\", line 59, in request\n    return session.request(method=method, url=url, **kwargs)\n           ^^^^^^^^^^^^^^^^^^^^^^^^^^^^^^^^^^^^^^^^^^^^^^^^^\n  File \"/opt/conda/envs/cf-scripts/lib/python3.11/site-packages/requests/sessions.py\", line 589, in request\n    resp = self.send(prep, **send_kwargs)\n           ^^^^^^^^^^^^^^^^^^^^^^^^^^^^^^\n  File \"/opt/conda/envs/cf-scripts/lib/python3.11/site-packages/requests/sessions.py\", line 703, in send\n    r = adapter.send(request, **kwargs)\n        ^^^^^^^^^^^^^^^^^^^^^^^^^^^^^^^\n  File \"/opt/conda/envs/cf-scripts/lib/python3.11/site-packages/requests/adapters.py\", line 682, in send\n    raise ConnectionError(err, request=request)\nrequests.exceptions.ConnectionError: ('Connection aborted.', RemoteDisconnected('Remote end closed connection without response'))\n"
 }
}