{
 "PRed": [
  {
   "PR": {
    "labels": [],
    "number": 2,
    "state": "closed"
   },
   "data": {
    "bot_rerun": false,
    "migrator_name": "MigrationYaml",
    "migrator_object_version": 1,
    "migrator_version": 0,
    "name": "python312"
   },
   "keys": [
    "bot_rerun",
    "migrator_name",
    "migrator_object_version",
    "migrator_version",
    "name"
   ]
  },
  {
   "PR": {
    "labels": [],
    "number": 3,
    "state": "closed"
   },
   "data": {
    "bot_rerun": false,
    "migrator_name": "MigrationYaml",
    "migrator_object_version": 1,
    "migrator_version": 0,
    "name": "pypy38"
   },
   "keys": [
    "bot_rerun",
    "migrator_name",
    "migrator_object_version",
    "migrator_version",
    "name"
   ]
  }
 ],
 "bad": {
  "exception": "Error running 'conda-forge-tick-container migrate-feedstock --feedstock-name llvm-bazel-cache --default-branch main --existing-feedstock-node-attrs - --log-level info --kwargs {\n \"hash_type\": \"sha256\"\n}' in container - error UnboundLocalError raised:\n\"cannot access local variable 'url' where it is not associated with a value\"",
  "traceback": [
   "Traceback (most recent call last):",
   "  File \"/opt/autotick-bot/conda_forge_tick/container_cli.py\", line 119, in _run_bot_task",
   "    data = func(attrs=attrs, **kwargs)",
   "           ^^^^^^^^^^^^^^^^^^^^^^^^^^^",
   "  File \"/opt/autotick-bot/conda_forge_tick/container_cli.py\", line 225, in _migrate_feedstock",
   "    data = run_migration_local(",
   "           ^^^^^^^^^^^^^^^^^^^^",
   "  File \"/opt/autotick-bot/conda_forge_tick/migration_runner.py\", line 251, in run_migration_local",
   "    data[\"migrate_return_value\"] = migrator.migrate(",
   "                                   ^^^^^^^^^^^^^^^^^",
   "  File \"/opt/autotick-bot/conda_forge_tick/migrators/version.py\", line 230, in migrate",
   "    updated_meta_yaml, errors = update_version(",
   "                                ^^^^^^^^^^^^^^^",
   "  File \"/opt/autotick-bot/conda_forge_tick/update_recipe/version.py\", line 889, in update_version",
   "    _did_update, _errors = _try_to_update_version(",
   "                           ^^^^^^^^^^^^^^^^^^^^^^^",
   "  File \"/opt/autotick-bot/conda_forge_tick/update_recipe/version.py\", line 516, in _try_to_update_version",
   "    new_url_tmpl, new_hash = _get_new_url_tmpl_and_hash(",
   "                             ^^^^^^^^^^^^^^^^^^^^^^^^^^^",
   "  File \"/opt/autotick-bot/conda_forge_tick/update_recipe/version.py\", line 312, in _get_new_url_tmpl_and_hash",
   "    if url != url_tmpl:",
   "       ^^^",
   "UnboundLocalError: cannot access local variable 'url' where it is not associated with a value",
   ""
  ]
 },
 "pinning_version": "2024.04.13.08.49.00",
 "pre_pr_migrator_attempts": {},
 "pre_pr_migrator_status": {},
 "smithy_version": "3.34.1"
}