{
 "bad": false,
 "pre_pr_migrator_attempts": {
  "noarch_python_min": 3,
  "version": 1
 },
 "pre_pr_migrator_status": {
  "noarch_python_min": "not solvable (<a href='https://github.com/regro/cf-scripts/actions/runs/12883123411'>bot CI job</a>) @ main\n        <details>\n        <div align=\"left\">\n        <pre>\n        linux_64_: Cannot solve the request because of: python >=3.9 cannot be installed because there are no viable options:\n\u2514\u2500 python 3.12.0rc3 | 3.13.0rc1 | 3.13.0rc1 | 3.13.0rc1 | 3.13.0rc1 | 3.13.0rc1 | 3.13.0rc1 | 3.13.0rc2 | 3.13.0rc2 | 3.13.0rc2 | 3.13.0rc2 | 3.13.0rc2 | 3.13.0rc2 | 3.13.0rc2 | 3.13.0rc2 | 3.13.0rc3 | 3.13.0rc3 would require\n   \u2514\u2500 _python_rc *, for which no candidates were found.\nThe following packages are incompatible\n\u251C\u2500 python >=3.9 can be installed with any of the following options:\n\u2502  \u251C\u2500 python 3.13.0 | 3.13.0 | 3.13.1 | 3.13.1 | 3.13.1 | 3.13.1 | 3.13.1 would require\n\u2502  \u2502  \u2514\u2500 python_abi 3.13.* *_cp313, which can be installed with any of the following options:\n\u2502  \u2502     \u2514\u2500 python_abi 3.13\n\u2502  \u251C\u2500 python 3.13.0 | 3.13.0 | 3.13.1 | 3.13.1 | 3.13.1 | 3.13.1 | 3.13.1 would require\n\u2502  \u2502  \u2514\u2500 python_abi 3.13.* *_cp313t, which can be installed with any of the following options:\n\u2502  \u2502     \u2514\u2500 python_abi 3.13\n\u2502  \u2514\u2500 python 3.9.0 | 3.9.0 | 3.9.0 | 3.9.0 | 3.9.0 | 3.9.1 | 3.9.1 | 3.9.1 | 3.9.1 | 3.9.1 | 3.9.1 | 3.9.2 | 3.9.4 | 3.9.5 | 3.9.6 | 3.9.6 | 3.9.7 | 3.9.7 | 3.9.7 | 3.9.7 | 3.9.7 | 3.9.9 | 3.9.9 | 3.9.10 | 3.9.10 | 3.9.10 | 3.9.10 | 3.9.10 | 3.9.10 | 3.9.10 | 3.9.12 | 3.9.12 | 3.9.12 | 3.9.12 | 3.9.12 | 3.9.13 | 3.9.13 | 3.9.14 | 3.9.14 | 3.9.15 | 3.9.15 | 3.9.16 | 3.9.16 | 3.9.17 | 3.9.17 | 3.9.18 | 3.9.18 | 3.9.18 | 3.9.18 | 3.9.19 | 3.9.20 | 3.9.20 | 3.9.21 | 3.10.0 | 3.10.0 | 3.10.0 | 3.10.0 | 3.10.0 | 3.10.0 | 3.10.1 | 3.10.1 | 3.10.1 | 3.10.1 | 3.10.1 | 3.10.1 | 3.10.2 | 3.10.2 | 3.10.2 | 3.10.2 | 3.10.2 | 3.10.2 | 3.10.2 | 3.10.2 | 3.10.2 | 3.10.2 | 3.10.4 | 3.10.4 | 3.10.5 | 3.10.5 | 3.10.6 | 3.10.6 | 3.10.7 | 3.10.7 | 3.10.8 | 3.10.8 | 3.10.8 | 3.10.9 | 3.10.10 | 3.10.11 | 3.10.12 | 3.10.13 | 3.10.13 | 3.10.14 | 3.10.15 | 3.10.15 | 3.10.15 | 3.10.16 | 3.11.0 | 3.11.0 | 3.11.0 | 3.11.0 | 3.11.1 | 3.11.2 | 3.11.3 | 3.11.4 | 3.11.5 | 3.11.6 | 3.11.7 | 3.11.7 | 3.11.8 | 3.11.9 | 3.11.10 | 3.11.10 | 3.11.10 | 3.11.10 | 3.11.11 | 3.12.0 | 3.12.1 | 3.12.1 | 3.12.2 | 3.12.3 | 3.12.4 | 3.12.5 | 3.12.6 | 3.12.6 | 3.12.6 | 3.12.7 | 3.12.8\n\u2514\u2500 docker-py >=3.4.1,<4.0.0 cannot be installed because there are no viable options:\n   \u251C\u2500 docker-py 3.5.0 | 3.5.1 | 3.5.1 | 3.6.0 | 3.7.0 | 3.7.1 | 3.7.2 would constrain\n   \u2502  \u2514\u2500 python_abi * *_cp37m, which conflicts with any installable versions previously reported\n   \u251C\u2500 docker-py 3.4.1 | 3.5.0 | 3.5.0 | 3.5.1 | 3.5.1 | 3.6.0 | 3.7.0 | 3.7.1 | 3.7.2 would constrain\n   \u2502  \u2514\u2500 python_abi * *_cp36m, which conflicts with any installable versions previously reported\n   \u251C\u2500 docker-py 3.4.1 | 3.5.0 would constrain\n   \u2502  \u2514\u2500 python_abi * *_cp35m, which conflicts with any installable versions previously reported\n   \u2514\u2500 docker-py 3.4.1 | 3.5.0 | 3.5.0 | 3.5.1 | 3.5.1 | 3.6.0 | 3.7.0 | 3.7.1 | 3.7.2 would constrain\n      \u2514\u2500 python_abi * *_cp27mu, which conflicts with any installable versions previously reported\n\n        </pre>\n        </div>\n        </details>",
  "version": "bot error: master: Traceback (most recent call last):\n  File \"/home/runner/work/autotick-bot/autotick-bot/cf-scripts/conda_forge_tick/git_utils.py\", line 135, in fetch_repo\n    _run_git_cmd(f\"git checkout --track upstream/{base_branch} {quiet}\")\n  File \"/home/runner/work/autotick-bot/autotick-bot/cf-scripts/conda_forge_tick/git_utils.py\", line 121, in _run_git_cmd\n    return subprocess.run(cmd, shell=True, check=True)\n  File \"/usr/share/miniconda/envs/run_env/lib/python3.8/subprocess.py\", line 512, in run\n    raise CalledProcessError(retcode, process.args,\nsubprocess.CalledProcessError: Command 'git checkout --track upstream/master --quiet' returned non-zero exit status 128.\n\nDuring handling of the above exception, another exception occurred:\n\nTraceback (most recent call last):\n  File \"/home/runner/work/autotick-bot/autotick-bot/cf-scripts/conda_forge_tick/auto_tick.py\", line 1018, in main\n    migrator_uid, pr_json = run(\n  File \"/home/runner/work/autotick-bot/autotick-bot/cf-scripts/conda_forge_tick/auto_tick.py\", line 163, in run\n    feedstock_dir, repo = get_repo(\n  File \"/home/runner/work/autotick-bot/autotick-bot/cf-scripts/conda_forge_tick/git_utils.py\", line 220, in get_repo\n    if fetch_repo(\n  File \"/home/runner/work/autotick-bot/autotick-bot/cf-scripts/conda_forge_tick/git_utils.py\", line 137, in fetch_repo\n    _run_git_cmd(\n  File \"/home/runner/work/autotick-bot/autotick-bot/cf-scripts/conda_forge_tick/git_utils.py\", line 121, in _run_git_cmd\n    return subprocess.run(cmd, shell=True, check=True)\n  File \"/usr/share/miniconda/envs/run_env/lib/python3.8/subprocess.py\", line 512, in run\n    raise CalledProcessError(retcode, process.args,\nsubprocess.CalledProcessError: Command 'git checkout -b master upstream/master --quiet' returned non-zero exit status 128.\n"
 }
}