{
 "bad": false,
 "pre_pr_migrator_attempts": {
  "noarch_python_min": 4
 },
 "pre_pr_migrator_status": {
  "noarch_python_min": "bot error (<a href=\"https://github.com/regro/cf-scripts/actions/runs/12925156060\">bot CI job</a>): main:\nTraceback (most recent call last):\n  File \"/home/runner/work/cf-scripts/cf-scripts/cf-scripts/conda_forge_tick/git_utils.py\", line 204, in _run_git_command\n    p = subprocess.run(\n        ^^^^^^^^^^^^^^^\n  File \"/home/runner/micromamba/envs/cf-scripts/lib/python3.11/subprocess.py\", line 571, in run\n    raise CalledProcessError(retcode, process.args,\nsubprocess.CalledProcessError: Command '['git', 'clone', '--quiet', 'https://github.com/regro-cf-autotick-bot/drmaa-feedstock.git', PosixPath('/home/runner/work/_temp/tmpw6_qws3o/drmaa-feedstock')]' returned non-zero exit status 128.\n\nDuring handling of the above exception, another exception occurred:\n\nTraceback (most recent call last):\n  File \"/home/runner/work/cf-scripts/cf-scripts/cf-scripts/conda_forge_tick/git_utils.py\", line 281, in clone_repo\n    self._run_git_command([\"clone\", \"--quiet\", origin_url, target_dir])\n  File \"/home/runner/micromamba/envs/cf-scripts/lib/python3.11/contextlib.py\", line 81, in inner\n    return func(*args, **kwds)\n           ^^^^^^^^^^^^^^^^^^^\n  File \"/home/runner/work/cf-scripts/cf-scripts/cf-scripts/conda_forge_tick/git_utils.py\", line 216, in _run_git_command\n    raise GitCliError(f\"Error running git command: {repr(e)}\")\nconda_forge_tick.git_utils.GitCliError: Error running git command: CalledProcessError(128, ['git', 'clone', '--quiet', 'https://github.com/regro-cf-autotick-bot/drmaa-feedstock.git', PosixPath('/home/runner/work/_temp/tmpw6_qws3o/drmaa-feedstock')])\n\nThe above exception was the direct cause of the following exception:\n\nTraceback (most recent call last):\n  File \"/home/runner/work/cf-scripts/cf-scripts/cf-scripts/conda_forge_tick/git_utils.py\", line 486, in clone_fork_and_branch\n    self.clone_repo(origin_url, target_dir)\n  File \"/home/runner/micromamba/envs/cf-scripts/lib/python3.11/contextlib.py\", line 81, in inner\n    return func(*args, **kwds)\n           ^^^^^^^^^^^^^^^^^^^\n  File \"/home/runner/work/cf-scripts/cf-scripts/cf-scripts/conda_forge_tick/git_utils.py\", line 283, in clone_repo\n    raise GitCliError(\nconda_forge_tick.git_utils.GitCliError: Error cloning repository from https://github.com/regro-cf-autotick-bot/drmaa-feedstock.git. Does the repository exist? Is target_dir empty?\n\nDuring handling of the above exception, another exception occurred:\n\nTraceback (most recent call last):\n  File \"/home/runner/work/cf-scripts/cf-scripts/cf-scripts/conda_forge_tick/git_utils.py\", line 204, in _run_git_command\n    p = subprocess.run(\n        ^^^^^^^^^^^^^^^\n  File \"/home/runner/micromamba/envs/cf-scripts/lib/python3.11/subprocess.py\", line 571, in run\n    raise CalledProcessError(retcode, process.args,\nsubprocess.CalledProcessError: Command '['git', 'reset', '--quiet', '--hard', 'HEAD']' returned non-zero exit status 128.\n\nDuring handling of the above exception, another exception occurred:\n\nTraceback (most recent call last):\n  File \"/home/runner/work/cf-scripts/cf-scripts/cf-scripts/conda_forge_tick/auto_tick.py\", line 744, in _run_migrator_on_feedstock_branch\n    migrator_uid, pr_json = run_with_tmpdir(\n                            ^^^^^^^^^^^^^^^^\n  File \"/home/runner/work/cf-scripts/cf-scripts/cf-scripts/conda_forge_tick/auto_tick.py\", line 451, in run_with_tmpdir\n    return run(\n           ^^^^\n  File \"/home/runner/work/cf-scripts/cf-scripts/cf-scripts/conda_forge_tick/auto_tick.py\", line 523, in run\n    if not _prepare_feedstock_repository(\n           ^^^^^^^^^^^^^^^^^^^^^^^^^^^^^^\n  File \"/home/runner/work/cf-scripts/cf-scripts/cf-scripts/conda_forge_tick/auto_tick.py\", line 181, in _prepare_feedstock_repository\n    backend.clone_fork_and_branch(\n  File \"/home/runner/micromamba/envs/cf-scripts/lib/python3.11/contextlib.py\", line 81, in inner\n    return func(*args, **kwds)\n           ^^^^^^^^^^^^^^^^^^^\n  File \"/home/runner/work/cf-scripts/cf-scripts/cf-scripts/conda_forge_tick/git_utils.py\", line 641, in clone_fork_and_branch\n    self.cli.clone_fork_and_branch(\n  File \"/home/runner/micromamba/envs/cf-scripts/lib/python3.11/contextlib.py\", line 81, in inner\n    return func(*args, **kwds)\n           ^^^^^^^^^^^^^^^^^^^\n  File \"/home/runner/work/cf-scripts/cf-scripts/cf-scripts/conda_forge_tick/git_utils.py\", line 497, in clone_fork_and_branch\n    self.reset_hard(target_dir)\n  File \"/home/runner/micromamba/envs/cf-scripts/lib/python3.11/contextlib.py\", line 81, in inner\n    return func(*args, **kwds)\n           ^^^^^^^^^^^^^^^^^^^\n  File \"/home/runner/work/cf-scripts/cf-scripts/cf-scripts/conda_forge_tick/git_utils.py\", line 266, in reset_hard\n    self._run_git_command([\"reset\", \"--quiet\", \"--hard\", to_treeish], git_dir)\n  File \"/home/runner/micromamba/envs/cf-scripts/lib/python3.11/contextlib.py\", line 81, in inner\n    return func(*args, **kwds)\n           ^^^^^^^^^^^^^^^^^^^\n  File \"/home/runner/work/cf-scripts/cf-scripts/cf-scripts/conda_forge_tick/git_utils.py\", line 216, in _run_git_command\n    raise GitCliError(f\"Error running git command: {repr(e)}\")\nconda_forge_tick.git_utils.GitCliError: Error running git command: CalledProcessError(128, ['git', 'reset', '--quiet', '--hard', 'HEAD'])\n"
 }
}