{
 "bad": false,
 "new_version": "0.3.16",
 "new_version_attempts": {
  "0.0.10": 1,
  "0.0.11": 1,
  "0.0.12": 1,
  "0.0.13": 1,
  "0.0.14": 1,
  "0.0.15": 1,
  "0.0.16": 1,
  "0.0.17": 1,
  "0.0.18": 1,
  "0.0.19": 1,
  "0.0.20": 1,
  "0.0.21": 1,
  "0.0.22": 1,
  "0.0.24": 1,
  "0.0.25": 1,
  "0.0.26": 1,
  "0.0.27": 1,
  "0.0.28": 1,
  "0.0.29": 1,
  "0.0.3": 4,
  "0.0.30": 1,
  "0.0.31": 1,
  "0.0.32": 1,
  "0.0.33": 1,
  "0.0.34": 1,
  "0.0.35": 1,
  "0.0.36": 1,
  "0.0.37": 1,
  "0.0.38": 1,
  "0.0.4": 4,
  "0.0.5": 3,
  "0.0.6": 8,
  "0.0.7": 1,
  "0.0.8": 1,
  "0.0.9": 1,
  "0.2.0": 1,
  "0.3.10": 1,
  "0.3.16": 1
 },
 "new_version_errors": {
  "0.0.3": "The recipe did not change in the version migration, a URL did not hash, or there is jinja2 syntax the bot cannot handle!\n\nPlease check the URLs in your recipe with version '0.0.3' to make sure they exist!\n\nWe also found the following errors:\n\n - We found a problem parsing the recipe for version '0.0.3': \n\nDuplicateKeyError('while constructing a mapping',   in \"<unicode string>\", line 109, column 3:\n      home: https://github.com/langcha ... \n      ^ (line: 109), 'found duplicate key \"summary\" with value \"Community contributed LangChain integrations.\" (original value: \"Community contributed LangChain integrations.\")',   in \"<unicode string>\", line 113, column 3:\n      summary: Community contributed L ... \n      ^ (line: 113), '\\n                    To suppress this check see:\\n                        http://yaml.readthedocs.io/en/latest/api.html#duplicate-keys\\n                    ', '                    Duplicate keys will become an error in future releases, and are errors\\n                    by default when using the new API.\\n                    ')\n\ntraceback:\n  File \"/home/runner/work/cf-scripts/cf-scripts/cf-scripts/conda_forge_tick/update_recipe/version.py\", line 411, in update_version\n    cmeta = CondaMetaYAML(raw_meta_yaml)\n  File \"/home/runner/work/cf-scripts/cf-scripts/cf-scripts/conda_forge_tick/recipe_parser/_parser.py\", line 514, in __init__\n    self.meta = self._parser.load(\"\".join(lines))\n  File \"/home/runner/micromamba/envs/cf-scripts/lib/python3.10/site-packages/ruamel/yaml/main.py\", line 451, in load\n    return constructor.get_single_data()\n  File \"/home/runner/micromamba/envs/cf-scripts/lib/python3.10/site-packages/ruamel/yaml/constructor.py\", line 114, in get_single_data\n    return self.construct_document(node)\n  File \"/home/runner/micromamba/envs/cf-scripts/lib/python3.10/site-packages/ruamel/yaml/constructor.py\", line 123, in construct_document\n    for _dummy in generator:\n  File \"/home/runner/micromamba/envs/cf-scripts/lib/python3.10/site-packages/ruamel/yaml/constructor.py\", line 1470, in construct_yaml_map\n    self.construct_mapping(node, data, deep=True)\n  File \"/home/runner/micromamba/envs/cf-scripts/lib/python3.10/site-packages/ruamel/yaml/constructor.py\", line 1359, in construct_mapping\n    value = self.construct_object(value_node, deep=deep)\n  File \"/home/runner/micromamba/envs/cf-scripts/lib/python3.10/site-packages/ruamel/yaml/constructor.py\", line 145, in construct_object\n    data = self.construct_non_recursive_object(node)\n  File \"/home/runner/micromamba/envs/cf-scripts/lib/python3.10/site-packages/ruamel/yaml/constructor.py\", line 186, in construct_non_recursive_object\n    for _dummy in generator:\n  File \"/home/runner/micromamba/envs/cf-scripts/lib/python3.10/site-packages/ruamel/yaml/constructor.py\", line 1470, in construct_yaml_map\n    self.construct_mapping(node, data, deep=True)\n  File \"/home/runner/micromamba/envs/cf-scripts/lib/python3.10/site-packages/ruamel/yaml/constructor.py\", line 1360, in construct_mapping\n    if self.check_mapping_key(node, key_node, maptyp, key, value):\n  File \"/home/runner/micromamba/envs/cf-scripts/lib/python3.10/site-packages/ruamel/yaml/constructor.py\", line 276, in check_mapping_key\n    raise DuplicateKeyError(*args)\n\n",
  "0.0.4": "The recipe did not change in the version migration, a URL did not hash, or there is jinja2 syntax the bot cannot handle!\n\nPlease check the URLs in your recipe with version '0.0.4' to make sure they exist!\n\nWe also found the following errors:\n\n - We found a problem parsing the recipe for version '0.0.4': \n\nDuplicateKeyError('while constructing a mapping',   in \"<unicode string>\", line 109, column 3:\n      home: https://github.com/langcha ... \n      ^ (line: 109), 'found duplicate key \"summary\" with value \"Community contributed LangChain integrations.\" (original value: \"Community contributed LangChain integrations.\")',   in \"<unicode string>\", line 113, column 3:\n      summary: Community contributed L ... \n      ^ (line: 113), '\\n                    To suppress this check see:\\n                        http://yaml.readthedocs.io/en/latest/api.html#duplicate-keys\\n                    ', '                    Duplicate keys will become an error in future releases, and are errors\\n                    by default when using the new API.\\n                    ')\n\ntraceback:\n  File \"/home/runner/work/cf-scripts/cf-scripts/cf-scripts/conda_forge_tick/update_recipe/version.py\", line 411, in update_version\n    cmeta = CondaMetaYAML(raw_meta_yaml)\n  File \"/home/runner/work/cf-scripts/cf-scripts/cf-scripts/conda_forge_tick/recipe_parser/_parser.py\", line 514, in __init__\n    self.meta = self._parser.load(\"\".join(lines))\n  File \"/home/runner/micromamba/envs/cf-scripts/lib/python3.10/site-packages/ruamel/yaml/main.py\", line 451, in load\n    return constructor.get_single_data()\n  File \"/home/runner/micromamba/envs/cf-scripts/lib/python3.10/site-packages/ruamel/yaml/constructor.py\", line 114, in get_single_data\n    return self.construct_document(node)\n  File \"/home/runner/micromamba/envs/cf-scripts/lib/python3.10/site-packages/ruamel/yaml/constructor.py\", line 123, in construct_document\n    for _dummy in generator:\n  File \"/home/runner/micromamba/envs/cf-scripts/lib/python3.10/site-packages/ruamel/yaml/constructor.py\", line 1470, in construct_yaml_map\n    self.construct_mapping(node, data, deep=True)\n  File \"/home/runner/micromamba/envs/cf-scripts/lib/python3.10/site-packages/ruamel/yaml/constructor.py\", line 1359, in construct_mapping\n    value = self.construct_object(value_node, deep=deep)\n  File \"/home/runner/micromamba/envs/cf-scripts/lib/python3.10/site-packages/ruamel/yaml/constructor.py\", line 145, in construct_object\n    data = self.construct_non_recursive_object(node)\n  File \"/home/runner/micromamba/envs/cf-scripts/lib/python3.10/site-packages/ruamel/yaml/constructor.py\", line 186, in construct_non_recursive_object\n    for _dummy in generator:\n  File \"/home/runner/micromamba/envs/cf-scripts/lib/python3.10/site-packages/ruamel/yaml/constructor.py\", line 1470, in construct_yaml_map\n    self.construct_mapping(node, data, deep=True)\n  File \"/home/runner/micromamba/envs/cf-scripts/lib/python3.10/site-packages/ruamel/yaml/constructor.py\", line 1360, in construct_mapping\n    if self.check_mapping_key(node, key_node, maptyp, key, value):\n  File \"/home/runner/micromamba/envs/cf-scripts/lib/python3.10/site-packages/ruamel/yaml/constructor.py\", line 276, in check_mapping_key\n    raise DuplicateKeyError(*args)\n\n",
  "0.0.5": "The recipe did not change in the version migration, a URL did not hash, or there is jinja2 syntax the bot cannot handle!\n\nPlease check the URLs in your recipe with version '0.0.5' to make sure they exist!\n\nWe also found the following errors:\n\n - We found a problem parsing the recipe for version '0.0.5': \n\nDuplicateKeyError('while constructing a mapping',   in \"<unicode string>\", line 109, column 3:\n      home: https://github.com/langcha ... \n      ^ (line: 109), 'found duplicate key \"summary\" with value \"Community contributed LangChain integrations.\" (original value: \"Community contributed LangChain integrations.\")',   in \"<unicode string>\", line 113, column 3:\n      summary: Community contributed L ... \n      ^ (line: 113), '\\n                    To suppress this check see:\\n                        http://yaml.readthedocs.io/en/latest/api.html#duplicate-keys\\n                    ', '                    Duplicate keys will become an error in future releases, and are errors\\n                    by default when using the new API.\\n                    ')\n\ntraceback:\n  File \"/home/runner/work/cf-scripts/cf-scripts/cf-scripts/conda_forge_tick/update_recipe/version.py\", line 411, in update_version\n    cmeta = CondaMetaYAML(raw_meta_yaml)\n  File \"/home/runner/work/cf-scripts/cf-scripts/cf-scripts/conda_forge_tick/recipe_parser/_parser.py\", line 514, in __init__\n    self.meta = self._parser.load(\"\".join(lines))\n  File \"/home/runner/micromamba/envs/cf-scripts/lib/python3.10/site-packages/ruamel/yaml/main.py\", line 451, in load\n    return constructor.get_single_data()\n  File \"/home/runner/micromamba/envs/cf-scripts/lib/python3.10/site-packages/ruamel/yaml/constructor.py\", line 114, in get_single_data\n    return self.construct_document(node)\n  File \"/home/runner/micromamba/envs/cf-scripts/lib/python3.10/site-packages/ruamel/yaml/constructor.py\", line 123, in construct_document\n    for _dummy in generator:\n  File \"/home/runner/micromamba/envs/cf-scripts/lib/python3.10/site-packages/ruamel/yaml/constructor.py\", line 1470, in construct_yaml_map\n    self.construct_mapping(node, data, deep=True)\n  File \"/home/runner/micromamba/envs/cf-scripts/lib/python3.10/site-packages/ruamel/yaml/constructor.py\", line 1359, in construct_mapping\n    value = self.construct_object(value_node, deep=deep)\n  File \"/home/runner/micromamba/envs/cf-scripts/lib/python3.10/site-packages/ruamel/yaml/constructor.py\", line 145, in construct_object\n    data = self.construct_non_recursive_object(node)\n  File \"/home/runner/micromamba/envs/cf-scripts/lib/python3.10/site-packages/ruamel/yaml/constructor.py\", line 186, in construct_non_recursive_object\n    for _dummy in generator:\n  File \"/home/runner/micromamba/envs/cf-scripts/lib/python3.10/site-packages/ruamel/yaml/constructor.py\", line 1470, in construct_yaml_map\n    self.construct_mapping(node, data, deep=True)\n  File \"/home/runner/micromamba/envs/cf-scripts/lib/python3.10/site-packages/ruamel/yaml/constructor.py\", line 1360, in construct_mapping\n    if self.check_mapping_key(node, key_node, maptyp, key, value):\n  File \"/home/runner/micromamba/envs/cf-scripts/lib/python3.10/site-packages/ruamel/yaml/constructor.py\", line 276, in check_mapping_key\n    raise DuplicateKeyError(*args)\n\n",
  "0.0.6": "The recipe did not change in the version migration, a URL did not hash, or there is jinja2 syntax the bot cannot handle!\n\nPlease check the URLs in your recipe with version '0.0.6' to make sure they exist!\n\nWe also found the following errors:\n\n - We found a problem parsing the recipe for version '0.0.6': \n\nDuplicateKeyError('while constructing a mapping',   in \"<unicode string>\", line 109, column 3:\n      home: https://github.com/langcha ... \n      ^ (line: 109), 'found duplicate key \"summary\" with value \"Community contributed LangChain integrations.\" (original value: \"Community contributed LangChain integrations.\")',   in \"<unicode string>\", line 113, column 3:\n      summary: Community contributed L ... \n      ^ (line: 113), '\\n                    To suppress this check see:\\n                        http://yaml.readthedocs.io/en/latest/api.html#duplicate-keys\\n                    ', '                    Duplicate keys will become an error in future releases, and are errors\\n                    by default when using the new API.\\n                    ')\n\ntraceback:\n  File \"/home/runner/work/cf-scripts/cf-scripts/cf-scripts/conda_forge_tick/update_recipe/version.py\", line 411, in update_version\n    cmeta = CondaMetaYAML(raw_meta_yaml)\n  File \"/home/runner/work/cf-scripts/cf-scripts/cf-scripts/conda_forge_tick/recipe_parser/_parser.py\", line 514, in __init__\n    self.meta = self._parser.load(\"\".join(lines))\n  File \"/home/runner/miniconda3/envs/cf-scripts/lib/python3.10/site-packages/ruamel/yaml/main.py\", line 451, in load\n    return constructor.get_single_data()\n  File \"/home/runner/miniconda3/envs/cf-scripts/lib/python3.10/site-packages/ruamel/yaml/constructor.py\", line 114, in get_single_data\n    return self.construct_document(node)\n  File \"/home/runner/miniconda3/envs/cf-scripts/lib/python3.10/site-packages/ruamel/yaml/constructor.py\", line 123, in construct_document\n    for _dummy in generator:\n  File \"/home/runner/miniconda3/envs/cf-scripts/lib/python3.10/site-packages/ruamel/yaml/constructor.py\", line 1470, in construct_yaml_map\n    self.construct_mapping(node, data, deep=True)\n  File \"/home/runner/miniconda3/envs/cf-scripts/lib/python3.10/site-packages/ruamel/yaml/constructor.py\", line 1359, in construct_mapping\n    value = self.construct_object(value_node, deep=deep)\n  File \"/home/runner/miniconda3/envs/cf-scripts/lib/python3.10/site-packages/ruamel/yaml/constructor.py\", line 145, in construct_object\n    data = self.construct_non_recursive_object(node)\n  File \"/home/runner/miniconda3/envs/cf-scripts/lib/python3.10/site-packages/ruamel/yaml/constructor.py\", line 186, in construct_non_recursive_object\n    for _dummy in generator:\n  File \"/home/runner/miniconda3/envs/cf-scripts/lib/python3.10/site-packages/ruamel/yaml/constructor.py\", line 1470, in construct_yaml_map\n    self.construct_mapping(node, data, deep=True)\n  File \"/home/runner/miniconda3/envs/cf-scripts/lib/python3.10/site-packages/ruamel/yaml/constructor.py\", line 1360, in construct_mapping\n    if self.check_mapping_key(node, key_node, maptyp, key, value):\n  File \"/home/runner/miniconda3/envs/cf-scripts/lib/python3.10/site-packages/ruamel/yaml/constructor.py\", line 276, in check_mapping_key\n    raise DuplicateKeyError(*args)\n\n",
  "0.3.10": "bot error (<a href=\"https://github.com/regro/cf-scripts/actions/runs/12215785856\">bot CI job</a>): main:\nError running 'conda-forge-feedstock-ops-container rerender --log-level info --timeout 900' in container - error RuntimeError raised:\n'Failed to rerender.\noutput: Traceback (most recent call last):\n  File \"/opt/conda/envs/cf-scripts/bin/conda-smithy\", line 10, in <module>\n    sys.exit(main())\n             ^^^^^^\n  File \"/opt/conda/envs/cf-scripts/lib/python3.11/site-packages/conda_smithy/cli.py\", line 767, in main\n    args.subcommand_func(args)\n  File \"/opt/conda/envs/cf-scripts/lib/python3.11/site-packages/conda_smithy/cli.py\", line 610, in __call__\n    self._call(args, args.temporary_directory)\n  File \"/opt/conda/envs/cf-scripts/lib/python3.11/site-packages/conda_smithy/cli.py\", line 613, in _call\n    configure_feedstock.main(\n  File \"/opt/conda/envs/cf-scripts/lib/python3.11/site-packages/conda_smithy/configure_feedstock.py\", line 2843, in main\n    exclusive_config_file, cf_pinning_ver = get_cached_cfp_file_path(\n                                            ^^^^^^^^^^^^^^^^^^^^^^^^^\n  File \"/opt/conda/envs/cf-scripts/lib/python3.11/site-packages/conda_smithy/configure_feedstock.py\", line 2656, in get_cached_cfp_file_path\n    current_pinning_version = get_most_recent_version(\n                              ^^^^^^^^^^^^^^^^^^^^^^^^\n  File \"/opt/conda/envs/cf-scripts/lib/python3.11/site-packages/conda_smithy/configure_feedstock.py\", line 2529, in get_most_recent_version\n    request.raise_for_status()\n  File \"/opt/conda/envs/cf-scripts/lib/python3.11/site-packages/requests/models.py\", line 1024, in raise_for_status\n    raise HTTPError(http_error_msg, response=self)\nrequests.exceptions.HTTPError: 524 Server Error:  for url: https://api.anaconda.org/package/conda-forge/conda-forge-pinning\n\n'",
  "0.3.16": "bot error (<a href=\"https://github.com/regro/cf-scripts/actions/runs/13012603665\">bot CI job</a>): main:\nTraceback (most recent call last):\n  File \"/home/runner/micromamba/envs/cf-scripts/lib/python3.11/site-packages/urllib3/connectionpool.py\", line 467, in _make_request\n    six.raise_from(e, None)\n  File \"<string>\", line 3, in raise_from\n  File \"/home/runner/micromamba/envs/cf-scripts/lib/python3.11/site-packages/urllib3/connectionpool.py\", line 462, in _make_request\n    httplib_response = conn.getresponse()\n                       ^^^^^^^^^^^^^^^^^^\n  File \"/home/runner/micromamba/envs/cf-scripts/lib/python3.11/http/client.py\", line 1395, in getresponse\n    response.begin()\n  File \"/home/runner/micromamba/envs/cf-scripts/lib/python3.11/http/client.py\", line 325, in begin\n    version, status, reason = self._read_status()\n                              ^^^^^^^^^^^^^^^^^^^\n  File \"/home/runner/micromamba/envs/cf-scripts/lib/python3.11/http/client.py\", line 286, in _read_status\n    line = str(self.fp.readline(_MAXLINE + 1), \"iso-8859-1\")\n               ^^^^^^^^^^^^^^^^^^^^^^^^^^^^^^\n  File \"/home/runner/micromamba/envs/cf-scripts/lib/python3.11/socket.py\", line 718, in readinto\n    return self._sock.recv_into(b)\n           ^^^^^^^^^^^^^^^^^^^^^^^\n  File \"/home/runner/micromamba/envs/cf-scripts/lib/python3.11/ssl.py\", line 1314, in recv_into\n    return self.read(nbytes, buffer)\n           ^^^^^^^^^^^^^^^^^^^^^^^^^\n  File \"/home/runner/micromamba/envs/cf-scripts/lib/python3.11/ssl.py\", line 1166, in read\n    return self._sslobj.read(len, buffer)\n           ^^^^^^^^^^^^^^^^^^^^^^^^^^^^^^\nTimeoutError: The read operation timed out\n\nDuring handling of the above exception, another exception occurred:\n\nTraceback (most recent call last):\n  File \"/home/runner/micromamba/envs/cf-scripts/lib/python3.11/site-packages/requests/adapters.py\", line 667, in send\n    resp = conn.urlopen(\n           ^^^^^^^^^^^^^\n  File \"/home/runner/micromamba/envs/cf-scripts/lib/python3.11/site-packages/urllib3/connectionpool.py\", line 801, in urlopen\n    retries = retries.increment(\n              ^^^^^^^^^^^^^^^^^^\n  File \"/home/runner/micromamba/envs/cf-scripts/lib/python3.11/site-packages/urllib3/util/retry.py\", line 552, in increment\n    raise six.reraise(type(error), error, _stacktrace)\n          ^^^^^^^^^^^^^^^^^^^^^^^^^^^^^^^^^^^^^^^^^^^^\n  File \"/home/runner/micromamba/envs/cf-scripts/lib/python3.11/site-packages/urllib3/packages/six.py\", line 770, in reraise\n    raise value\n  File \"/home/runner/micromamba/envs/cf-scripts/lib/python3.11/site-packages/urllib3/connectionpool.py\", line 715, in urlopen\n    httplib_response = self._make_request(\n                       ^^^^^^^^^^^^^^^^^^^\n  File \"/home/runner/micromamba/envs/cf-scripts/lib/python3.11/site-packages/urllib3/connectionpool.py\", line 469, in _make_request\n    self._raise_timeout(err=e, url=url, timeout_value=read_timeout)\n  File \"/home/runner/micromamba/envs/cf-scripts/lib/python3.11/site-packages/urllib3/connectionpool.py\", line 358, in _raise_timeout\n    raise ReadTimeoutError(\nurllib3.exceptions.ReadTimeoutError: HTTPSConnectionPool(host='api.github.com', port=443): Read timed out. (read timeout=10)\n\nDuring handling of the above exception, another exception occurred:\n\nTraceback (most recent call last):\n  File \"/home/runner/micromamba/envs/cf-scripts/lib/python3.11/site-packages/github3/models.py\", line 201, in _request\n    return request_method(*args, **kwargs)\n           ^^^^^^^^^^^^^^^^^^^^^^^^^^^^^^^\n  File \"/home/runner/work/cf-scripts/cf-scripts/cf-scripts/conda_forge_tick/git_utils.py\", line 751, in post\n    return self._forward_request(self._session.post, *args, **kwargs)\n           ^^^^^^^^^^^^^^^^^^^^^^^^^^^^^^^^^^^^^^^^^^^^^^^^^^^^^^^^^^\n  File \"/home/runner/work/cf-scripts/cf-scripts/cf-scripts/conda_forge_tick/git_utils.py\", line 746, in _forward_request\n    response = method(*args, **kwargs)\n               ^^^^^^^^^^^^^^^^^^^^^^^\n  File \"/home/runner/micromamba/envs/cf-scripts/lib/python3.11/site-packages/requests/sessions.py\", line 637, in post\n    return self.request(\"POST\", url, data=data, json=json, **kwargs)\n           ^^^^^^^^^^^^^^^^^^^^^^^^^^^^^^^^^^^^^^^^^^^^^^^^^^^^^^^^^\n  File \"/home/runner/micromamba/envs/cf-scripts/lib/python3.11/site-packages/github3/session.py\", line 171, in request\n    response = super().request(*args, **kwargs)\n               ^^^^^^^^^^^^^^^^^^^^^^^^^^^^^^^^\n  File \"/home/runner/micromamba/envs/cf-scripts/lib/python3.11/site-packages/requests/sessions.py\", line 589, in request\n    resp = self.send(prep, **send_kwargs)\n           ^^^^^^^^^^^^^^^^^^^^^^^^^^^^^^\n  File \"/home/runner/micromamba/envs/cf-scripts/lib/python3.11/site-packages/requests/sessions.py\", line 703, in send\n    r = adapter.send(request, **kwargs)\n        ^^^^^^^^^^^^^^^^^^^^^^^^^^^^^^^\n  File \"/home/runner/micromamba/envs/cf-scripts/lib/python3.11/site-packages/requests/adapters.py\", line 713, in send\n    raise ReadTimeout(e, request=request)\nrequests.exceptions.ReadTimeout: HTTPSConnectionPool(host='api.github.com', port=443): Read timed out. (read timeout=10)\n\nDuring handling of the above exception, another exception occurred:\n\nTraceback (most recent call last):\n  File \"/home/runner/work/cf-scripts/cf-scripts/cf-scripts/conda_forge_tick/auto_tick.py\", line 744, in _run_migrator_on_feedstock_branch\n    migrator_uid, pr_json = run_with_tmpdir(\n                            ^^^^^^^^^^^^^^^^\n  File \"/home/runner/work/cf-scripts/cf-scripts/cf-scripts/conda_forge_tick/auto_tick.py\", line 451, in run_with_tmpdir\n    return run(\n           ^^^^\n  File \"/home/runner/work/cf-scripts/cf-scripts/cf-scripts/conda_forge_tick/auto_tick.py\", line 626, in run\n    pr_data = git_backend.create_pull_request(\n              ^^^^^^^^^^^^^^^^^^^^^^^^^^^^^^^^\n  File \"/home/runner/work/cf-scripts/cf-scripts/cf-scripts/conda_forge_tick/git_utils.py\", line 928, in create_pull_request\n    response: github3.pulls.ShortPullRequest | None = repo.create_pull(\n                                                      ^^^^^^^^^^^^^^^^^\n  File \"/home/runner/micromamba/envs/cf-scripts/lib/python3.11/site-packages/github3/decorators.py\", line 24, in auth_wrapper\n    return func(self, *args, **kwargs)\n           ^^^^^^^^^^^^^^^^^^^^^^^^^^^\n  File \"/home/runner/micromamba/envs/cf-scripts/lib/python3.11/site-packages/github3/repos/repo.py\", line 1185, in create_pull\n    return self._create_pull(data)\n           ^^^^^^^^^^^^^^^^^^^^^^^\n  File \"/home/runner/micromamba/envs/cf-scripts/lib/python3.11/site-packages/github3/repos/repo.py\", line 117, in _create_pull\n    json = self._json(self._post(url, data=data), 201)\n                      ^^^^^^^^^^^^^^^^^^^^^^^^^^\n  File \"/home/runner/micromamba/envs/cf-scripts/lib/python3.11/site-packages/github3/models.py\", line 226, in _post\n    return self._request(\"post\", url, data, **kwargs)\n           ^^^^^^^^^^^^^^^^^^^^^^^^^^^^^^^^^^^^^^^^^^\n  File \"/home/runner/micromamba/envs/cf-scripts/lib/python3.11/site-packages/github3/models.py\", line 206, in _request\n    raise exceptions.ConnectionError(exc)\ngithub3.exceptions.ConnectionError: <class 'requests.exceptions.ReadTimeout'>: A connection-level exception occurred: HTTPSConnectionPool(host='api.github.com', port=443): Read timed out. (read timeout=10)\n"
 }
}