{
 "bad": false,
 "new_version": "3.2.0",
 "new_version_attempts": {
  "1.16.0": 1,
  "1.17.0": 1,
  "1.18.0": 1,
  "1.19.0": 1,
  "1.20.0": 1,
  "1.21.0": 1,
  "1.22.0": 1,
  "1.23.0": 1,
  "1.24.0": 5.200000000000002,
  "1.25.0": 8.0,
  "1.26.0": 1.4,
  "1.27.0": 4.000000000000001,
  "1.28.0": 2.5999999999999996,
  "1.29.0": 2.3999999999999995,
  "1.30.0": 4.400000000000001,
  "1.31.0": 5.000000000000002,
  "1.32.0": 2.8,
  "2.0.0": 3.200000000000001,
  "2.1.0": 4.000000000000001,
  "2.2.0": 3.0,
  "2.3.0": 2.3999999999999995,
  "2.4.0": 3.000000000000001,
  "2.5.0": 3.4000000000000012,
  "2.6.0": 4.200000000000001,
  "2.7.0": 3.000000000000001,
  "2.7.1": 3.000000000000001,
  "2.7.2": 3.000000000000001,
  "2.7.3": 3.000000000000001,
  "2.7.4": 4.000000000000001,
  "2.8.0": 5.200000000000002,
  "2.9.0": 6.800000000000003,
  "3.0.0": 3.000000000000001,
  "3.2.0": 3.2
 },
 "new_version_errors": {
  "1.24.0": "not solvable (<a href=\"https://github.com/regro/autotick-bot/actions/runs/1939378312\">bot CI job</a>): master: ['linux_64_: Encountered problems while solving:\\n  - nothing provides requested certbot >=1.24.0\\n']",
  "1.25.0": "not solvable (<a href=\"https://github.com/regro/autotick-bot/actions/runs/2056198085\">bot CI job</a>): main: ['linux_64_: Encountered problems while solving:\\n  - nothing provides requested certbot >=1.25.0\\n']",
  "1.26.0": "not solvable (<a href=\"https://github.com/regro/autotick-bot/actions/runs/2101794629\">bot CI job</a>): main: ['linux_64_: Encountered problems while solving:\\n  - nothing provides requested acme >=1.26.0\\n  - nothing provides requested certbot >=1.26.0\\n']",
  "1.27.0": "not solvable (<a href=\"https://github.com/regro/autotick-bot/actions/runs/2287551306\">bot CI job</a>): main: ['linux_64_: Encountered problems while solving:\\n  - nothing provides requested certbot >=1.27.0\\n']",
  "1.28.0": "not solvable (<a href=\"https://github.com/regro/autotick-bot/actions/runs/2466810671\">bot CI job</a>): main: ['linux_64_: Encountered problems while solving:\\n  - nothing provides requested certbot >=1.28.0\\n']",
  "1.29.0": "not solvable (<a href=\"https://github.com/regro/autotick-bot/actions/runs/2631734595\">bot CI job</a>): main: ['linux_64_: Encountered problems while solving:\\n  - nothing provides requested certbot >=1.29.0\\n']",
  "1.30.0": "not solvable (<a href=\"https://github.com/regro/autotick-bot/actions/runs/3031156076\">bot CI job</a>): main: ['linux_64_: Encountered problems while solving:\\n  - nothing provides requested certbot >=1.30.0\\n']",
  "1.31.0": "not solvable (<a href=\"https://github.com/regro/autotick-bot/actions/runs/3218992995\">bot CI job</a>): main: ['linux_64_: Encountered problems while solving:\\n  - nothing provides requested certbot >=1.31.0\\n']",
  "1.32.0": "not solvable (<a href=\"https://github.com/regro/autotick-bot/actions/runs/3436479424\">bot CI job</a>): main: ['linux_64_: Encountered problems while solving:\\n  - nothing provides requested certbot >=1.32.0\\n']",
  "2.0.0": "not solvable (<a href=\"https://github.com/regro/autotick-bot/actions/runs/3611140740\">bot CI job</a>): main: ['linux_64_: Encountered problems while solving:\\n  - nothing provides requested certbot >=2.0.0\\n']",
  "2.1.0": "not solvable (<a href=\"https://github.com/regro/autotick-bot/actions/runs/3665907033\">bot CI job</a>): main: ['linux_64_: Encountered problems while solving:\\n  - nothing provides requested certbot >=2.1.0\\n']",
  "2.2.0": "not solvable (<a href=\"https://github.com/regro/autotick-bot/actions/runs/3918467109\">bot CI job</a>): main: ['linux_64_: Encountered problems while solving:\\n  - nothing provides requested certbot >=2.2.0\\n']",
  "2.3.0": "not solvable (<a href=\"https://github.com/regro/autotick-bot/actions/runs/4194589630\">bot CI job</a>): main: ['linux_64_: Encountered problems while solving:\\n  - nothing provides requested certbot >=2.3.0\\n']",
  "2.4.0": "not solvable (<a href=\"https://github.com/regro/cf-scripts/actions/runs/4390181952\">bot CI job</a>): main: ['linux_64_: Encountered problems while solving:\\n  - nothing provides requested certbot >=2.4.0\\n  - nothing provides requested acme >=2.4.0\\n']",
  "2.5.0": "not solvable (<a href=\"https://github.com/regro/cf-scripts/actions/runs/4710379190\">bot CI job</a>): main: ['linux_64_: Encountered problems while solving:\\n  - nothing provides requested acme >=2.5.0\\n  - nothing provides requested certbot >=2.5.0\\n']",
  "2.6.0": "not solvable (<a href=\"https://github.com/regro/cf-scripts/actions/runs/4971390163\">bot CI job</a>): main: ['linux_64_: Encountered problems while solving:\\n  - nothing provides requested certbot >=2.6.0\\n  - nothing provides requested acme >=2.6.0\\n']",
  "2.7.0": "not solvable (<a href=\"https://github.com/regro/cf-scripts/actions/runs/6440808893\">bot CI job</a>): main: ['linux_64_: Could not solve for environment specs\\nThe following packages are incompatible\\n\u251C\u2500 acme >=2.7.0  does not exist (perhaps a typo or a missing channel);\\n\u2514\u2500 certbot >=2.7.0  does not exist (perhaps a typo or a missing channel).']",
  "2.7.1": "not solvable (<a href='https://github.com/regro/cf-scripts/actions/runs/6516652386'>bot CI job</a>) @ main\n                <details>\n                <div align=\"left\">\n                <pre>\n                linux_64_: Could not solve for environment specs\nThe following package could not be installed\n\u2514\u2500 certbot >=2.7.1  does not exist (perhaps a typo or a missing channel).\n                </pre>\n                </div>\n                </details>",
  "2.7.2": "not solvable (<a href='https://github.com/regro/cf-scripts/actions/runs/6601587260'>bot CI job</a>) @ main\n                <details>\n                <div align=\"left\">\n                <pre>\n                linux_64_: Could not solve for environment specs\nThe following packages are incompatible\n\u251C\u2500 acme >=2.7.2  does not exist (perhaps a typo or a missing channel);\n\u2514\u2500 certbot >=2.7.2  does not exist (perhaps a typo or a missing channel).\n                </pre>\n                </div>\n                </details>",
  "2.7.3": "not solvable (<a href='https://github.com/regro/cf-scripts/actions/runs/6682410274'>bot CI job</a>) @ main\n                <details>\n                <div align=\"left\">\n                <pre>\n                linux_64_: Could not solve for environment specs\nThe following packages are incompatible\n\u251C\u2500 acme >=2.7.3  does not exist (perhaps a typo or a missing channel);\n\u2514\u2500 certbot >=2.7.3  does not exist (perhaps a typo or a missing channel).\n                </pre>\n                </div>\n                </details>",
  "2.7.4": "not solvable (<a href='https://github.com/regro/cf-scripts/actions/runs/6757096621'>bot CI job</a>) @ main\n                <details>\n                <div align=\"left\">\n                <pre>\n                linux_64_: Could not solve for environment specs\nThe following package could not be installed\n\u2514\u2500 certbot >=2.7.4  does not exist (perhaps a typo or a missing channel).\n                </pre>\n                </div>\n                </details>",
  "2.8.0": "not solvable (<a href='https://github.com/regro/cf-scripts/actions/runs/7335843913'>bot CI job</a>) @ main\n                <details>\n                <div align=\"left\">\n                <pre>\n                linux_64_: Could not solve for environment specs\nThe following package could not be installed\n\u2514\u2500 certbot >=2.8.0  does not exist (perhaps a typo or a missing channel).\n                </pre>\n                </div>\n                </details>",
  "2.9.0": "not solvable (<a href='https://github.com/regro/cf-scripts/actions/runs/8520373253'>bot CI job</a>) @ main\n                <details>\n                <div align=\"left\">\n                <pre>\n                linux_64_: Could not solve for environment specs\nThe following packages are incompatible\n\u251C\u2500 acme >=2.9.0  does not exist (perhaps a typo or a missing channel);\n\u2514\u2500 certbot >=2.9.0  does not exist (perhaps a typo or a missing channel).\n                </pre>\n                </div>\n                </details>",
  "3.0.0": "not solvable (<a href='https://github.com/regro/cf-scripts/actions/runs/11772752982'>bot CI job</a>) @ main\n<details>\n<div align=\"left\">\n<pre>\nlinux_64_: Cannot solve the request because of: No candidates were found for certbot >=3.0.0.\n\n</pre>\n</div>\n</details>",
  "3.2.0": "bot error (<a href=\"https://github.com/regro/cf-scripts/actions/runs/13286275317\">bot CI job</a>): main:\nTraceback (most recent call last):\n  File \"/opt/conda/envs/cf-scripts/lib/python3.11/site-packages/urllib3/connectionpool.py\", line 715, in urlopen\n    httplib_response = self._make_request(\n                       ^^^^^^^^^^^^^^^^^^^\n  File \"/opt/conda/envs/cf-scripts/lib/python3.11/site-packages/urllib3/connectionpool.py\", line 467, in _make_request\n    six.raise_from(e, None)\n  File \"<string>\", line 3, in raise_from\n  File \"/opt/conda/envs/cf-scripts/lib/python3.11/site-packages/urllib3/connectionpool.py\", line 462, in _make_request\n    httplib_response = conn.getresponse()\n                       ^^^^^^^^^^^^^^^^^^\n  File \"/opt/conda/envs/cf-scripts/lib/python3.11/http/client.py\", line 1395, in getresponse\n    response.begin()\n  File \"/opt/conda/envs/cf-scripts/lib/python3.11/http/client.py\", line 325, in begin\n    version, status, reason = self._read_status()\n                              ^^^^^^^^^^^^^^^^^^^\n  File \"/opt/conda/envs/cf-scripts/lib/python3.11/http/client.py\", line 294, in _read_status\n    raise RemoteDisconnected(\"Remote end closed connection without\"\nhttp.client.RemoteDisconnected: Remote end closed connection without response\n\nDuring handling of the above exception, another exception occurred:\n\nTraceback (most recent call last):\n  File \"/opt/conda/envs/cf-scripts/lib/python3.11/site-packages/requests/adapters.py\", line 667, in send\n    resp = conn.urlopen(\n           ^^^^^^^^^^^^^\n  File \"/opt/conda/envs/cf-scripts/lib/python3.11/site-packages/urllib3/connectionpool.py\", line 801, in urlopen\n    retries = retries.increment(\n              ^^^^^^^^^^^^^^^^^^\n  File \"/opt/conda/envs/cf-scripts/lib/python3.11/site-packages/urllib3/util/retry.py\", line 552, in increment\n    raise six.reraise(type(error), error, _stacktrace)\n          ^^^^^^^^^^^^^^^^^^^^^^^^^^^^^^^^^^^^^^^^^^^^\n  File \"/opt/conda/envs/cf-scripts/lib/python3.11/site-packages/urllib3/packages/six.py\", line 769, in reraise\n    raise value.with_traceback(tb)\n  File \"/opt/conda/envs/cf-scripts/lib/python3.11/site-packages/urllib3/connectionpool.py\", line 715, in urlopen\n    httplib_response = self._make_request(\n                       ^^^^^^^^^^^^^^^^^^^\n  File \"/opt/conda/envs/cf-scripts/lib/python3.11/site-packages/urllib3/connectionpool.py\", line 467, in _make_request\n    six.raise_from(e, None)\n  File \"<string>\", line 3, in raise_from\n  File \"/opt/conda/envs/cf-scripts/lib/python3.11/site-packages/urllib3/connectionpool.py\", line 462, in _make_request\n    httplib_response = conn.getresponse()\n                       ^^^^^^^^^^^^^^^^^^\n  File \"/opt/conda/envs/cf-scripts/lib/python3.11/http/client.py\", line 1395, in getresponse\n    response.begin()\n  File \"/opt/conda/envs/cf-scripts/lib/python3.11/http/client.py\", line 325, in begin\n    version, status, reason = self._read_status()\n                              ^^^^^^^^^^^^^^^^^^^\n  File \"/opt/conda/envs/cf-scripts/lib/python3.11/http/client.py\", line 294, in _read_status\n    raise RemoteDisconnected(\"Remote end closed connection without\"\nurllib3.exceptions.ProtocolError: ('Connection aborted.', RemoteDisconnected('Remote end closed connection without response'))\n\nDuring handling of the above exception, another exception occurred:\n\nTraceback (most recent call last):\n  File \"/opt/autotick-bot/conda_forge_tick/container_cli.py\", line 119, in _run_bot_task\n    data = func(attrs=attrs, **kwargs)\n           ^^^^^^^^^^^^^^^^^^^^^^^^^^^\n  File \"/opt/autotick-bot/conda_forge_tick/container_cli.py\", line 225, in _migrate_feedstock\n    data = run_migration_local(\n           ^^^^^^^^^^^^^^^^^^^^\n  File \"/opt/autotick-bot/conda_forge_tick/migration_runner.py\", line 260, in run_migration_local\n    data[\"pr_body\"] = migrator.pr_body(feedstock_ctx)\n                      ^^^^^^^^^^^^^^^^^^^^^^^^^^^^^^^\n  File \"/opt/autotick-bot/conda_forge_tick/migrators/version.py\", line 265, in pr_body\n    pred = [\n           ^\n  File \"/opt/autotick-bot/conda_forge_tick/migrators/version.py\", line 268, in <listcomp>\n    self.effective_graph.nodes[name][\"payload\"][\"version_pr_info\"][\n  File \"/opt/autotick-bot/conda_forge_tick/lazy_json_backends.py\", line 1052, in __getitem__\n    self._load()\n  File \"/opt/autotick-bot/conda_forge_tick/lazy_json_backends.py\", line 1009, in _load\n    backend.hsetnx(self.hashmap, self.node, dumps({}))\n  File \"/opt/autotick-bot/conda_forge_tick/lazy_json_backends.py\", line 114, in hsetnx\n    if self.hexists(name, key):\n       ^^^^^^^^^^^^^^^^^^^^^^^\n  File \"/opt/autotick-bot/conda_forge_tick/lazy_json_backends.py\", line 256, in hexists\n    status = requests.head(url, allow_redirects=True).status_code\n             ^^^^^^^^^^^^^^^^^^^^^^^^^^^^^^^^^^^^^^^^\n  File \"/opt/conda/envs/cf-scripts/lib/python3.11/site-packages/requests/api.py\", line 100, in head\n    return request(\"head\", url, **kwargs)\n           ^^^^^^^^^^^^^^^^^^^^^^^^^^^^^^\n  File \"/opt/conda/envs/cf-scripts/lib/python3.11/site-packages/requests/api.py\", line 59, in request\n    return session.request(method=method, url=url, **kwargs)\n           ^^^^^^^^^^^^^^^^^^^^^^^^^^^^^^^^^^^^^^^^^^^^^^^^^\n  File \"/opt/conda/envs/cf-scripts/lib/python3.11/site-packages/requests/sessions.py\", line 589, in request\n    resp = self.send(prep, **send_kwargs)\n           ^^^^^^^^^^^^^^^^^^^^^^^^^^^^^^\n  File \"/opt/conda/envs/cf-scripts/lib/python3.11/site-packages/requests/sessions.py\", line 703, in send\n    r = adapter.send(request, **kwargs)\n        ^^^^^^^^^^^^^^^^^^^^^^^^^^^^^^^\n  File \"/opt/conda/envs/cf-scripts/lib/python3.11/site-packages/requests/adapters.py\", line 682, in send\n    raise ConnectionError(err, request=request)\nrequests.exceptions.ConnectionError: ('Connection aborted.', RemoteDisconnected('Remote end closed connection without response'))\n"
 }
}