{
 "bad": false,
 "new_version": "0.51b0",
 "new_version_attempts": {
  "0.24b0": 3.6000000000000005,
  "0.25b0": 1.4,
  "0.25b1": 1.7999999999999998,
  "0.25b2": 4.400000000000001,
  "0.26b1": 1.4,
  "0.27b0": 1.5999999999999999,
  "0.28b0": 6.600000000000004,
  "0.28b1": 8.200000000000003,
  "0.29b0": 1.4,
  "0.30b0": 1.4,
  "0.30b1": 2.6000000000000005,
  "0.31b0": 6.0000000000000036,
  "0.32b0": 8.0,
  "0.33b0": 2.2,
  "0.34b0": 23,
  "0.35b0": 9,
  "0.36b0": 4,
  "0.37b0": 1.4,
  "0.38b0": 1.2,
  "0.39b0": 1.2,
  "0.40b0": 1.2,
  "0.41b0": 1,
  "0.42b0": 4.400000000000001,
  "0.43b0": 1,
  "0.44b0": 1.2,
  "0.45b0": 2.8000000000000007,
  "0.51b0": 2.3999999999999995
 },
 "new_version_errors": {
  "0.24b0": "not solvable (<a href=\"https://github.com/regro/autotick-bot/actions/runs/1237119766\">bot CI job</a>): master: ['linux_64_: Encountered problems while solving:\\n  - nothing provides requested opentelemetry-api ~=1.3.*\\n']",
  "0.25b0": "not solvable (<a href=\"https://github.com/regro/autotick-bot/actions/runs/1340586332\">bot CI job</a>): master: ['linux_64_: Encountered problems while solving:\\n  - nothing provides requested opentelemetry-instrumentation 0.25b0.*\\n']",
  "0.25b1": "not solvable (<a href=\"https://github.com/regro/autotick-bot/actions/runs/1359380785\">bot CI job</a>): master: ['linux_64_: Encountered problems while solving:\\n  - nothing provides requested opentelemetry-instrumentation 0.25b1.*\\n']",
  "0.25b2": "not solvable (<a href=\"https://github.com/regro/autotick-bot/actions/runs/1378362668\">bot CI job</a>): master: ['linux_64_: Encountered problems while solving:\\n  - nothing provides requested opentelemetry-semantic-conventions 0.25b2.*\\n']",
  "0.26b1": "not solvable (<a href=\"https://github.com/regro/autotick-bot/actions/runs/1451859402\">bot CI job</a>): master: ['linux_64_: Encountered problems while solving:\\n  - nothing provides requested opentelemetry-semantic-conventions 0.26b1.*\\n']",
  "0.27b0": "not solvable (<a href=\"https://github.com/regro/autotick-bot/actions/runs/1594851977\">bot CI job</a>): master: ['linux_64_: Encountered problems while solving:\\n  - package opentelemetry-sdk-1.3.0-pyhd8ed1ab_0 requires opentelemetry-api 1.3.0, but none of the providers can be installed\\n']",
  "0.28b0": "not solvable (<a href=\"https://github.com/regro/autotick-bot/actions/runs/1771608900\">bot CI job</a>): master: ['linux_64_: Encountered problems while solving:\\n  - package opentelemetry-instrumentation-0.28b0-pyhd8ed1ab_0 requires opentelemetry-api ~=1.4, but none of the providers can be installed\\n']",
  "0.28b1": "not solvable (<a href=\"https://github.com/regro/autotick-bot/actions/runs/1797959963\">bot CI job</a>): master: ['linux_64_: Encountered problems while solving:\\n  - package opentelemetry-sdk-1.3.0-pyhd8ed1ab_0 requires opentelemetry-api 1.3.0, but none of the providers can be installed\\n']",
  "0.29b0": "not solvable (<a href=\"https://github.com/regro/autotick-bot/actions/runs/1967883922\">bot CI job</a>): master: ['linux_64_: Encountered problems while solving:\\n  - package opentelemetry-instrumentation-0.29b0-pyhd8ed1ab_0 requires opentelemetry-api ~=1.4, but none of the providers can be installed\\n']",
  "0.30b0": "not solvable (<a href=\"https://github.com/regro/autotick-bot/actions/runs/2186772502\">bot CI job</a>): main: ['linux_64_: Encountered problems while solving:\\n  - package opentelemetry-sdk-1.3.0-pyhd8ed1ab_0 requires opentelemetry-api 1.3.0, but none of the providers can be installed\\n']",
  "0.30b1": "not solvable (<a href=\"https://github.com/regro/autotick-bot/actions/runs/2207285687\">bot CI job</a>): main: ['linux_64_: Encountered problems while solving:\\n  - package opentelemetry-sdk-1.3.0-pyhd8ed1ab_0 requires opentelemetry-api 1.3.0, but none of the providers can be installed\\n']",
  "0.31b0": "not solvable (<a href=\"https://github.com/regro/autotick-bot/actions/runs/2604260686\">bot CI job</a>): main: ['linux_64_: Encountered problems while solving:\\n  - package opentelemetry-sdk-1.3.0-pyhd8ed1ab_0 requires opentelemetry-api 1.3.0, but none of the providers can be installed\\n']",
  "0.32b0": "not solvable (<a href=\"https://github.com/regro/autotick-bot/actions/runs/2825249047\">bot CI job</a>): main: ['linux_64_: Encountered problems while solving:\\n  - package opentelemetry-sdk-1.3.0-pyhd8ed1ab_0 requires opentelemetry-api 1.3.0, but none of the providers can be installed\\n']",
  "0.33b0": "not solvable (<a href=\"https://github.com/regro/autotick-bot/actions/runs/2830318186\">bot CI job</a>): main: ['linux_64_: Encountered problems while solving:\\n  - nothing provides requested opentelemetry-instrumentation 0.33b0.*\\n  - nothing provides requested opentelemetry-sdk ~=1.12\\n']",
  "0.34b0": "The recipe did not change in the version migration, a URL did not hash, or there is jinja2 syntax the bot cannot handle!\n\nPlease check the URLs in your recipe with version '0.34b0' to make sure they exist!\n\nWe also found the following errors:\n\n - could not hash URL template 'https://pypi.io/packages/source/{{ name[0] }}/{{ name }}/opentelemetry-instrumentation-sqlalchemy-{{ version }}.tar.gz'\n",
  "0.35b0": "The recipe did not change in the version migration, a URL did not hash, or there is jinja2 syntax the bot cannot handle!\n\nPlease check the URLs in your recipe with version '0.35b0' to make sure they exist!\n\nWe also found the following errors:\n\n - could not hash URL template 'https://pypi.io/packages/source/{{ name[0] }}/{{ name }}/opentelemetry-instrumentation-sqlalchemy-{{ version }}.tar.gz'\n",
  "0.36b0": "The recipe did not change in the version migration, a URL did not hash, or there is jinja2 syntax the bot cannot handle!\n\nPlease check the URLs in your recipe with version '0.36b0' to make sure they exist!\n\nWe also found the following errors:\n\n - could not hash URL template 'https://pypi.io/packages/source/{{ name[0] }}/{{ name }}/opentelemetry-instrumentation-sqlalchemy-{{ version }}.tar.gz'\n",
  "0.37b0": "not solvable (<a href=\"https://github.com/regro/autotick-bot/actions/runs/4210132254\">bot CI job</a>): main: ['linux_64_: Encountered problems while solving:\\n  - nothing provides requested opentelemetry-instrumentation 0.37b0.*\\n']",
  "0.38b0": "not solvable (<a href=\"https://github.com/regro/cf-scripts/actions/runs/4492635696\">bot CI job</a>): main: ['linux_64_: Encountered problems while solving:\\n  - nothing provides requested opentelemetry-semantic-conventions 0.38b0.*\\n  - nothing provides requested opentelemetry-instrumentation 0.38b0.*\\n']",
  "0.39b0": "not solvable (<a href=\"https://github.com/regro/cf-scripts/actions/runs/5028409694\">bot CI job</a>): main: ['linux_64_: Encountered problems while solving:\\n  - nothing provides requested opentelemetry-semantic-conventions 0.39b0.*\\n  - nothing provides requested opentelemetry-instrumentation 0.39b0.*\\n']",
  "0.40b0": "not solvable (<a href=\"https://github.com/regro/cf-scripts/actions/runs/5547117127\">bot CI job</a>): main: ['linux_64_: Encountered problems while solving:\\n  - nothing provides requested opentelemetry-instrumentation 0.40b0.*']",
  "0.42b0": "not solvable (<a href='https://github.com/regro/cf-scripts/actions/runs/6847975494'>bot CI job</a>) @ main\n                <details>\n                <div align=\"left\">\n                <pre>\n                linux_64_: Could not solve for environment specs\nThe following package could not be installed\n\u2514\u2500 opentelemetry-semantic-conventions 0.42b0.*  does not exist (perhaps a typo or a missing channel).\n                </pre>\n                </div>\n                </details>",
  "0.44b0": "not solvable (<a href='https://github.com/regro/cf-scripts/actions/runs/8025623581'>bot CI job</a>) @ main\n                <details>\n                <div align=\"left\">\n                <pre>\n                linux_64_: Could not solve for environment specs\nThe following packages are incompatible\n\u251C\u2500 opentelemetry-instrumentation 0.44b0.*  does not exist (perhaps a typo or a missing channel);\n\u2514\u2500 opentelemetry-semantic-conventions 0.44b0.*  does not exist (perhaps a typo or a missing channel).\n                </pre>\n                </div>\n                </details>",
  "0.45b0": "not solvable (<a href='https://github.com/regro/cf-scripts/actions/runs/8479436759'>bot CI job</a>) @ main\n                <details>\n                <div align=\"left\">\n                <pre>\n                linux_64_: Could not solve for environment specs\nThe following package could not be installed\n\u2514\u2500 opentelemetry-semantic-conventions 0.45b0.*  does not exist (perhaps a typo or a missing channel).\n                </pre>\n                </div>\n                </details>",
  "0.51b0": "bot error (<a href=\"https://github.com/regro/cf-scripts/actions/runs/13148251388\">bot CI job</a>): main:\nTraceback (most recent call last):\n  File \"/opt/conda/envs/cf-scripts/lib/python3.11/site-packages/conda_forge_feedstock_ops/__main__.py\", line 104, in _run_bot_task\n    data = func(**kwargs)\n           ^^^^^^^^^^^^^^\n  File \"/opt/conda/envs/cf-scripts/lib/python3.11/site-packages/conda_forge_feedstock_ops/__main__.py\", line 216, in _rerender_feedstock\n    msg = rerender_local(fs_dir, **kwargs)\n          ^^^^^^^^^^^^^^^^^^^^^^^^^^^^^^^^\n  File \"/opt/conda/envs/cf-scripts/lib/python3.11/site-packages/conda_forge_feedstock_ops/rerender.py\", line 255, in rerender_local\n    raise RuntimeError(f\"Failed to rerender.\noutput: {ret.stdout}\n\")\nRuntimeError: Failed to rerender.\noutput: Traceback (most recent call last):\n  File \"/opt/conda/envs/cf-scripts/bin/conda-smithy\", line 10, in <module>\n    sys.exit(main())\n             ^^^^^^\n  File \"/opt/conda/envs/cf-scripts/lib/python3.11/site-packages/conda_smithy/cli.py\", line 767, in main\n    args.subcommand_func(args)\n  File \"/opt/conda/envs/cf-scripts/lib/python3.11/site-packages/conda_smithy/cli.py\", line 610, in __call__\n    self._call(args, args.temporary_directory)\n  File \"/opt/conda/envs/cf-scripts/lib/python3.11/site-packages/conda_smithy/cli.py\", line 613, in _call\n    configure_feedstock.main(\n  File \"/opt/conda/envs/cf-scripts/lib/python3.11/site-packages/conda_smithy/configure_feedstock.py\", line 2858, in main\n    exclusive_config_file, cf_pinning_ver = get_cached_cfp_file_path(\n                                            ^^^^^^^^^^^^^^^^^^^^^^^^^\n  File \"/opt/conda/envs/cf-scripts/lib/python3.11/site-packages/conda_smithy/configure_feedstock.py\", line 2678, in get_cached_cfp_file_path\n    get_cfp_file_path(smithy_cache)\n  File \"/opt/conda/envs/cf-scripts/lib/python3.11/site-packages/conda_smithy/configure_feedstock.py\", line 2602, in get_cfp_file_path\n    pkg = get_most_recent_version(\"conda-forge-pinning\")\n          ^^^^^^^^^^^^^^^^^^^^^^^^^^^^^^^^^^^^^^^^^^^^^^\n  File \"/opt/conda/envs/cf-scripts/lib/python3.11/site-packages/conda_smithy/configure_feedstock.py\", line 2544, in get_most_recent_version\n    request.raise_for_status()\n  File \"/opt/conda/envs/cf-scripts/lib/python3.11/site-packages/requests/models.py\", line 1024, in raise_for_status\n    raise HTTPError(http_error_msg, response=self)\nrequests.exceptions.HTTPError: 520 Server Error:  for url: https://api.anaconda.org/package/conda-forge/conda-forge-pinning\n\n\n"
 }
}