{
 "bad": false,
 "new_version": "0.51b0",
 "new_version_attempts": {
  "0.24b0": 3.6000000000000005,
  "0.25b0": 1.2,
  "0.25b1": 1.5999999999999999,
  "0.25b2": 5.400000000000001,
  "0.26b1": 1.2,
  "0.27b0": 1.4,
  "0.28b0": 1.4,
  "0.28b1": 1.2,
  "0.29b0": 1.2,
  "0.30b0": 1.4,
  "0.30b1": 1.4,
  "0.31b0": 1.2,
  "0.32b0": 1.2,
  "0.33b0": 1.4,
  "0.34b0": 26,
  "0.35b0": 7,
  "0.36b0": 4,
  "0.37b0": 1.4,
  "0.38b0": 1.2,
  "0.39b0": 1.2,
  "0.40b0": 1.2,
  "0.41b0": 1,
  "0.42b0": 4.000000000000001,
  "0.43b0": 1,
  "0.44b0": 1.2,
  "0.45b0": 2.8000000000000007,
  "0.51b0": 3.6000000000000005
 },
 "new_version_errors": {
  "0.24b0": "not solvable (<a href=\"https://github.com/regro/autotick-bot/actions/runs/1237119766\">bot CI job</a>): master: ['linux_64_: Encountered problems while solving:\\n  - nothing provides requested opentelemetry-api ~=1.3.*\\n']",
  "0.25b0": "not solvable (<a href=\"https://github.com/regro/autotick-bot/actions/runs/1340586332\">bot CI job</a>): master: ['linux_64_: Encountered problems while solving:\\n  - nothing provides requested opentelemetry-instrumentation 0.25b0.*\\n']",
  "0.25b1": "not solvable (<a href=\"https://github.com/regro/autotick-bot/actions/runs/1358368512\">bot CI job</a>): master: ['linux_64_: Encountered problems while solving:\\n  - nothing provides requested opentelemetry-instrumentation 0.25b1.*\\n']",
  "0.25b2": "not solvable (<a href=\"https://github.com/regro/autotick-bot/actions/runs/1388693216\">bot CI job</a>): master: ['linux_64_: Encountered problems while solving:\\n  - nothing provides requested opentelemetry-semantic-conventions 0.25b2.*\\n']",
  "0.26b1": "not solvable (<a href=\"https://github.com/regro/autotick-bot/actions/runs/1451212486\">bot CI job</a>): master: ['linux_64_: Encountered problems while solving:\\n  - nothing provides requested opentelemetry-instrumentation 0.26b1.*\\n  - nothing provides requested opentelemetry-semantic-conventions 0.26b1.*\\n']",
  "0.27b0": "not solvable (<a href=\"https://github.com/regro/autotick-bot/actions/runs/1594242206\">bot CI job</a>): master: ['linux_64_: Encountered problems while solving:\\n  - nothing provides requested opentelemetry-instrumentation 0.27b0.*\\n  - nothing provides requested opentelemetry-semantic-conventions 0.27b0.*\\n']",
  "0.28b0": "not solvable (<a href=\"https://github.com/regro/autotick-bot/actions/runs/1755152736\">bot CI job</a>): master: ['linux_64_: Encountered problems while solving:\\n  - nothing provides requested opentelemetry-instrumentation 0.28b0.*\\n']",
  "0.28b1": "not solvable (<a href=\"https://github.com/regro/autotick-bot/actions/runs/1772581260\">bot CI job</a>): master: ['linux_64_: Encountered problems while solving:\\n  - nothing provides requested opentelemetry-instrumentation 0.28b1.*\\n  - nothing provides requested opentelemetry-semantic-conventions 0.28b1.*\\n']",
  "0.29b0": "not solvable (<a href=\"https://github.com/regro/autotick-bot/actions/runs/1967198842\">bot CI job</a>): master: ['linux_64_: Encountered problems while solving:\\n  - nothing provides requested opentelemetry-instrumentation 0.29b0.*\\n']",
  "0.30b0": "not solvable (<a href=\"https://github.com/regro/autotick-bot/actions/runs/2186248800\">bot CI job</a>): main: ['linux_64_: Encountered problems while solving:\\n  - nothing provides requested opentelemetry-semantic-conventions 0.30b0.*\\n  - nothing provides requested opentelemetry-instrumentation 0.30b0.*\\n']",
  "0.30b1": "not solvable (<a href=\"https://github.com/regro/autotick-bot/actions/runs/2205584524\">bot CI job</a>): main: ['linux_64_: Encountered problems while solving:\\n  - nothing provides requested opentelemetry-instrumentation 0.30b1.*\\n']",
  "0.31b0": "not solvable (<a href=\"https://github.com/regro/autotick-bot/actions/runs/2341821646\">bot CI job</a>): main: ['linux_64_: Encountered problems while solving:\\n  - nothing provides requested opentelemetry-semantic-conventions 0.31b0.*\\n  - nothing provides requested opentelemetry-instrumentation 0.31b0.*\\n']",
  "0.32b0": "not solvable (<a href=\"https://github.com/regro/autotick-bot/actions/runs/2611222436\">bot CI job</a>): main: ['linux_64_: Encountered problems while solving:\\n  - nothing provides requested opentelemetry-instrumentation 0.32b0.*\\n  - nothing provides requested opentelemetry-semantic-conventions 0.32b0.*\\n']",
  "0.33b0": "not solvable (<a href=\"https://github.com/regro/autotick-bot/actions/runs/2830318186\">bot CI job</a>): main: ['linux_64_: Encountered problems while solving:\\n  - nothing provides requested opentelemetry-instrumentation 0.33b0.*\\n']",
  "0.34b0": "The recipe did not change in the version migration, a URL did not hash, or there is jinja2 syntax the bot cannot handle!\n\nPlease check the URLs in your recipe with version '0.34b0' to make sure they exist!\n\nWe also found the following errors:\n\n - could not hash URL template 'https://pypi.io/packages/source/{{ name[0] }}/{{ name }}/opentelemetry-instrumentation-celery-{{ version }}.tar.gz'\n",
  "0.35b0": "The recipe did not change in the version migration, a URL did not hash, or there is jinja2 syntax the bot cannot handle!\n\nPlease check the URLs in your recipe with version '0.35b0' to make sure they exist!\n\nWe also found the following errors:\n\n - could not hash URL template 'https://pypi.io/packages/source/{{ name[0] }}/{{ name }}/opentelemetry-instrumentation-celery-{{ version }}.tar.gz'\n",
  "0.36b0": "The recipe did not change in the version migration, a URL did not hash, or there is jinja2 syntax the bot cannot handle!\n\nPlease check the URLs in your recipe with version '0.36b0' to make sure they exist!\n\nWe also found the following errors:\n\n - could not hash URL template 'https://pypi.io/packages/source/{{ name[0] }}/{{ name }}/opentelemetry-instrumentation-celery-{{ version }}.tar.gz'\n",
  "0.37b0": "not solvable (<a href=\"https://github.com/regro/autotick-bot/actions/runs/4210132254\">bot CI job</a>): main: ['linux_64_: Encountered problems while solving:\\n  - nothing provides requested opentelemetry-instrumentation 0.37b0.*\\n']",
  "0.38b0": "not solvable (<a href=\"https://github.com/regro/cf-scripts/actions/runs/4492635696\">bot CI job</a>): main: ['linux_64_: Encountered problems while solving:\\n  - nothing provides requested opentelemetry-semantic-conventions 0.38b0.*\\n  - nothing provides requested opentelemetry-instrumentation 0.38b0.*\\n']",
  "0.39b0": "not solvable (<a href=\"https://github.com/regro/cf-scripts/actions/runs/5028409694\">bot CI job</a>): main: ['linux_64_: Encountered problems while solving:\\n  - nothing provides requested opentelemetry-semantic-conventions 0.39b0.*\\n  - nothing provides requested opentelemetry-instrumentation 0.39b0.*\\n']",
  "0.40b0": "not solvable (<a href=\"https://github.com/regro/cf-scripts/actions/runs/5547117127\">bot CI job</a>): main: ['linux_64_: Encountered problems while solving:\\n  - nothing provides requested opentelemetry-instrumentation 0.40b0.*']",
  "0.42b0": "not solvable (<a href='https://github.com/regro/cf-scripts/actions/runs/6841641868'>bot CI job</a>) @ main\n                <details>\n                <div align=\"left\">\n                <pre>\n                linux_64_: Could not solve for environment specs\nThe following package could not be installed\n\u2514\u2500 opentelemetry-semantic-conventions 0.42b0.*  does not exist (perhaps a typo or a missing channel).\n                </pre>\n                </div>\n                </details>",
  "0.44b0": "not solvable (<a href='https://github.com/regro/cf-scripts/actions/runs/8026496315'>bot CI job</a>) @ main\n                <details>\n                <div align=\"left\">\n                <pre>\n                linux_64_: Could not solve for environment specs\nThe following packages are incompatible\n\u251C\u2500 opentelemetry-instrumentation 0.44b0.*  does not exist (perhaps a typo or a missing channel);\n\u2514\u2500 opentelemetry-semantic-conventions 0.44b0.*  does not exist (perhaps a typo or a missing channel).\n                </pre>\n                </div>\n                </details>",
  "0.45b0": "not solvable (<a href='https://github.com/regro/cf-scripts/actions/runs/8479436759'>bot CI job</a>) @ main\n                <details>\n                <div align=\"left\">\n                <pre>\n                linux_64_: Could not solve for environment specs\nThe following package could not be installed\n\u2514\u2500 opentelemetry-semantic-conventions 0.45b0.*  does not exist (perhaps a typo or a missing channel).\n                </pre>\n                </div>\n                </details>",
  "0.51b0": "bot error (<a href=\"https://github.com/regro/cf-scripts/actions/runs/13158273340\">bot CI job</a>): main:\nTraceback (most recent call last):\n  File \"/opt/conda/envs/cf-scripts/lib/python3.11/site-packages/urllib3/connectionpool.py\", line 715, in urlopen\n    httplib_response = self._make_request(\n                       ^^^^^^^^^^^^^^^^^^^\n  File \"/opt/conda/envs/cf-scripts/lib/python3.11/site-packages/urllib3/connectionpool.py\", line 467, in _make_request\n    six.raise_from(e, None)\n  File \"<string>\", line 3, in raise_from\n  File \"/opt/conda/envs/cf-scripts/lib/python3.11/site-packages/urllib3/connectionpool.py\", line 462, in _make_request\n    httplib_response = conn.getresponse()\n                       ^^^^^^^^^^^^^^^^^^\n  File \"/opt/conda/envs/cf-scripts/lib/python3.11/http/client.py\", line 1395, in getresponse\n    response.begin()\n  File \"/opt/conda/envs/cf-scripts/lib/python3.11/http/client.py\", line 325, in begin\n    version, status, reason = self._read_status()\n                              ^^^^^^^^^^^^^^^^^^^\n  File \"/opt/conda/envs/cf-scripts/lib/python3.11/http/client.py\", line 294, in _read_status\n    raise RemoteDisconnected(\"Remote end closed connection without\"\nhttp.client.RemoteDisconnected: Remote end closed connection without response\n\nDuring handling of the above exception, another exception occurred:\n\nTraceback (most recent call last):\n  File \"/opt/conda/envs/cf-scripts/lib/python3.11/site-packages/requests/adapters.py\", line 667, in send\n    resp = conn.urlopen(\n           ^^^^^^^^^^^^^\n  File \"/opt/conda/envs/cf-scripts/lib/python3.11/site-packages/urllib3/connectionpool.py\", line 801, in urlopen\n    retries = retries.increment(\n              ^^^^^^^^^^^^^^^^^^\n  File \"/opt/conda/envs/cf-scripts/lib/python3.11/site-packages/urllib3/util/retry.py\", line 552, in increment\n    raise six.reraise(type(error), error, _stacktrace)\n          ^^^^^^^^^^^^^^^^^^^^^^^^^^^^^^^^^^^^^^^^^^^^\n  File \"/opt/conda/envs/cf-scripts/lib/python3.11/site-packages/urllib3/packages/six.py\", line 769, in reraise\n    raise value.with_traceback(tb)\n  File \"/opt/conda/envs/cf-scripts/lib/python3.11/site-packages/urllib3/connectionpool.py\", line 715, in urlopen\n    httplib_response = self._make_request(\n                       ^^^^^^^^^^^^^^^^^^^\n  File \"/opt/conda/envs/cf-scripts/lib/python3.11/site-packages/urllib3/connectionpool.py\", line 467, in _make_request\n    six.raise_from(e, None)\n  File \"<string>\", line 3, in raise_from\n  File \"/opt/conda/envs/cf-scripts/lib/python3.11/site-packages/urllib3/connectionpool.py\", line 462, in _make_request\n    httplib_response = conn.getresponse()\n                       ^^^^^^^^^^^^^^^^^^\n  File \"/opt/conda/envs/cf-scripts/lib/python3.11/http/client.py\", line 1395, in getresponse\n    response.begin()\n  File \"/opt/conda/envs/cf-scripts/lib/python3.11/http/client.py\", line 325, in begin\n    version, status, reason = self._read_status()\n                              ^^^^^^^^^^^^^^^^^^^\n  File \"/opt/conda/envs/cf-scripts/lib/python3.11/http/client.py\", line 294, in _read_status\n    raise RemoteDisconnected(\"Remote end closed connection without\"\nurllib3.exceptions.ProtocolError: ('Connection aborted.', RemoteDisconnected('Remote end closed connection without response'))\n\nDuring handling of the above exception, another exception occurred:\n\nTraceback (most recent call last):\n  File \"/opt/autotick-bot/conda_forge_tick/container_cli.py\", line 119, in _run_bot_task\n    data = func(attrs=attrs, **kwargs)\n           ^^^^^^^^^^^^^^^^^^^^^^^^^^^\n  File \"/opt/autotick-bot/conda_forge_tick/container_cli.py\", line 197, in _migrate_feedstock\n    from conda_forge_tick.migrators import make_from_lazy_json_data\n  File \"/opt/autotick-bot/conda_forge_tick/migrators/__init__.py\", line 24, in <module>\n    from .dep_updates import DependencyUpdateMigrator\n  File \"/opt/autotick-bot/conda_forge_tick/migrators/dep_updates.py\", line 6, in <module>\n    from conda_forge_tick.update_deps import apply_dep_update, get_dep_updates_and_hints\n  File \"/opt/autotick-bot/conda_forge_tick/update_deps.py\", line 68, in <module>\n    r = requests.get(\n        ^^^^^^^^^^^^^\n  File \"/opt/conda/envs/cf-scripts/lib/python3.11/site-packages/requests/api.py\", line 73, in get\n    return request(\"get\", url, params=params, **kwargs)\n           ^^^^^^^^^^^^^^^^^^^^^^^^^^^^^^^^^^^^^^^^^^^^\n  File \"/opt/conda/envs/cf-scripts/lib/python3.11/site-packages/requests/api.py\", line 59, in request\n    return session.request(method=method, url=url, **kwargs)\n           ^^^^^^^^^^^^^^^^^^^^^^^^^^^^^^^^^^^^^^^^^^^^^^^^^\n  File \"/opt/conda/envs/cf-scripts/lib/python3.11/site-packages/requests/sessions.py\", line 589, in request\n    resp = self.send(prep, **send_kwargs)\n           ^^^^^^^^^^^^^^^^^^^^^^^^^^^^^^\n  File \"/opt/conda/envs/cf-scripts/lib/python3.11/site-packages/requests/sessions.py\", line 703, in send\n    r = adapter.send(request, **kwargs)\n        ^^^^^^^^^^^^^^^^^^^^^^^^^^^^^^^\n  File \"/opt/conda/envs/cf-scripts/lib/python3.11/site-packages/requests/adapters.py\", line 682, in send\n    raise ConnectionError(err, request=request)\nrequests.exceptions.ConnectionError: ('Connection aborted.', RemoteDisconnected('Remote end closed connection without response'))\n"
 }
}