{
 "PRed": [
  {
   "PR": {
    "labels": [
     {
      "name": "bot-rerun"
     }
    ],
    "number": 1,
    "state": "closed"
   },
   "data": {
    "bot_rerun": 1707347735.8775954,
    "migrator_name": "Version",
    "migrator_version": 0,
    "version": "1.3.1"
   },
   "keys": [
    "bot_rerun",
    "migrator_name",
    "migrator_version",
    "version"
   ]
  },
  {
   "PR": {
    "labels": [],
    "number": 2,
    "state": "closed"
   },
   "data": {
    "bot_rerun": false,
    "migrator_name": "Version",
    "migrator_version": 0,
    "version": "1.3.1"
   },
   "keys": [
    "bot_rerun",
    "migrator_name",
    "migrator_version",
    "version"
   ]
  }
 ],
 "bad": {
  "exception": "Error running 'conda-forge-tick-container migrate-feedstock --feedstock-name backports.strenum --default-branch main --existing-feedstock-node-attrs - --log-level info --kwargs {\n \"hash_type\": \"sha256\"\n}' in container - error ConnectionError raised:\nProtocolError('Connection aborted.', RemoteDisconnected('Remote end closed connection without response'))",
  "traceback": [
   "Traceback (most recent call last):",
   "  File \"/opt/conda/envs/cf-scripts/lib/python3.11/site-packages/urllib3/connectionpool.py\", line 715, in urlopen",
   "    httplib_response = self._make_request(",
   "                       ^^^^^^^^^^^^^^^^^^^",
   "  File \"/opt/conda/envs/cf-scripts/lib/python3.11/site-packages/urllib3/connectionpool.py\", line 467, in _make_request",
   "    six.raise_from(e, None)",
   "  File \"<string>\", line 3, in raise_from",
   "  File \"/opt/conda/envs/cf-scripts/lib/python3.11/site-packages/urllib3/connectionpool.py\", line 462, in _make_request",
   "    httplib_response = conn.getresponse()",
   "                       ^^^^^^^^^^^^^^^^^^",
   "  File \"/opt/conda/envs/cf-scripts/lib/python3.11/http/client.py\", line 1395, in getresponse",
   "    response.begin()",
   "  File \"/opt/conda/envs/cf-scripts/lib/python3.11/http/client.py\", line 325, in begin",
   "    version, status, reason = self._read_status()",
   "                              ^^^^^^^^^^^^^^^^^^^",
   "  File \"/opt/conda/envs/cf-scripts/lib/python3.11/http/client.py\", line 294, in _read_status",
   "    raise RemoteDisconnected(\"Remote end closed connection without\"",
   "http.client.RemoteDisconnected: Remote end closed connection without response",
   "",
   "During handling of the above exception, another exception occurred:",
   "",
   "Traceback (most recent call last):",
   "  File \"/opt/conda/envs/cf-scripts/lib/python3.11/site-packages/requests/adapters.py\", line 667, in send",
   "    resp = conn.urlopen(",
   "           ^^^^^^^^^^^^^",
   "  File \"/opt/conda/envs/cf-scripts/lib/python3.11/site-packages/urllib3/connectionpool.py\", line 801, in urlopen",
   "    retries = retries.increment(",
   "              ^^^^^^^^^^^^^^^^^^",
   "  File \"/opt/conda/envs/cf-scripts/lib/python3.11/site-packages/urllib3/util/retry.py\", line 552, in increment",
   "    raise six.reraise(type(error), error, _stacktrace)",
   "          ^^^^^^^^^^^^^^^^^^^^^^^^^^^^^^^^^^^^^^^^^^^^",
   "  File \"/opt/conda/envs/cf-scripts/lib/python3.11/site-packages/urllib3/packages/six.py\", line 769, in reraise",
   "    raise value.with_traceback(tb)",
   "  File \"/opt/conda/envs/cf-scripts/lib/python3.11/site-packages/urllib3/connectionpool.py\", line 715, in urlopen",
   "    httplib_response = self._make_request(",
   "                       ^^^^^^^^^^^^^^^^^^^",
   "  File \"/opt/conda/envs/cf-scripts/lib/python3.11/site-packages/urllib3/connectionpool.py\", line 467, in _make_request",
   "    six.raise_from(e, None)",
   "  File \"<string>\", line 3, in raise_from",
   "  File \"/opt/conda/envs/cf-scripts/lib/python3.11/site-packages/urllib3/connectionpool.py\", line 462, in _make_request",
   "    httplib_response = conn.getresponse()",
   "                       ^^^^^^^^^^^^^^^^^^",
   "  File \"/opt/conda/envs/cf-scripts/lib/python3.11/http/client.py\", line 1395, in getresponse",
   "    response.begin()",
   "  File \"/opt/conda/envs/cf-scripts/lib/python3.11/http/client.py\", line 325, in begin",
   "    version, status, reason = self._read_status()",
   "                              ^^^^^^^^^^^^^^^^^^^",
   "  File \"/opt/conda/envs/cf-scripts/lib/python3.11/http/client.py\", line 294, in _read_status",
   "    raise RemoteDisconnected(\"Remote end closed connection without\"",
   "urllib3.exceptions.ProtocolError: ('Connection aborted.', RemoteDisconnected('Remote end closed connection without response'))",
   "",
   "During handling of the above exception, another exception occurred:",
   "",
   "Traceback (most recent call last):",
   "  File \"/opt/autotick-bot/conda_forge_tick/container_cli.py\", line 119, in _run_bot_task",
   "    data = func(attrs=attrs, **kwargs)",
   "           ^^^^^^^^^^^^^^^^^^^^^^^^^^^",
   "  File \"/opt/autotick-bot/conda_forge_tick/container_cli.py\", line 197, in _migrate_feedstock",
   "    from conda_forge_tick.migrators import make_from_lazy_json_data",
   "  File \"/opt/autotick-bot/conda_forge_tick/migrators/__init__.py\", line 24, in <module>",
   "    from .dep_updates import DependencyUpdateMigrator",
   "  File \"/opt/autotick-bot/conda_forge_tick/migrators/dep_updates.py\", line 6, in <module>",
   "    from conda_forge_tick.update_deps import apply_dep_update, get_dep_updates_and_hints",
   "  File \"/opt/autotick-bot/conda_forge_tick/update_deps.py\", line 68, in <module>",
   "    r = requests.get(",
   "        ^^^^^^^^^^^^^",
   "  File \"/opt/conda/envs/cf-scripts/lib/python3.11/site-packages/requests/api.py\", line 73, in get",
   "    return request(\"get\", url, params=params, **kwargs)",
   "           ^^^^^^^^^^^^^^^^^^^^^^^^^^^^^^^^^^^^^^^^^^^^",
   "  File \"/opt/conda/envs/cf-scripts/lib/python3.11/site-packages/requests/api.py\", line 59, in request",
   "    return session.request(method=method, url=url, **kwargs)",
   "           ^^^^^^^^^^^^^^^^^^^^^^^^^^^^^^^^^^^^^^^^^^^^^^^^^",
   "  File \"/opt/conda/envs/cf-scripts/lib/python3.11/site-packages/requests/sessions.py\", line 589, in request",
   "    resp = self.send(prep, **send_kwargs)",
   "           ^^^^^^^^^^^^^^^^^^^^^^^^^^^^^^",
   "  File \"/opt/conda/envs/cf-scripts/lib/python3.11/site-packages/requests/sessions.py\", line 703, in send",
   "    r = adapter.send(request, **kwargs)",
   "        ^^^^^^^^^^^^^^^^^^^^^^^^^^^^^^^",
   "  File \"/opt/conda/envs/cf-scripts/lib/python3.11/site-packages/requests/adapters.py\", line 682, in send",
   "    raise ConnectionError(err, request=request)",
   "requests.exceptions.ConnectionError: ('Connection aborted.', RemoteDisconnected('Remote end closed connection without response'))",
   ""
  ]
 },
 "pinning_version": "2024.02.07.10.42.16",
 "pre_pr_migrator_attempts": {
  "noarch_python_min": 31
 },
 "pre_pr_migrator_status": {
  "noarch_python_min": "bot error (<a href=\"https://github.com/regro/cf-scripts/actions/runs/13054178157\">bot CI job</a>): main:\nTraceback (most recent call last):\n  File \"/opt/conda/envs/cf-scripts/lib/python3.11/site-packages/urllib3/connectionpool.py\", line 715, in urlopen\n    httplib_response = self._make_request(\n                       ^^^^^^^^^^^^^^^^^^^\n  File \"/opt/conda/envs/cf-scripts/lib/python3.11/site-packages/urllib3/connectionpool.py\", line 467, in _make_request\n    six.raise_from(e, None)\n  File \"<string>\", line 3, in raise_from\n  File \"/opt/conda/envs/cf-scripts/lib/python3.11/site-packages/urllib3/connectionpool.py\", line 462, in _make_request\n    httplib_response = conn.getresponse()\n                       ^^^^^^^^^^^^^^^^^^\n  File \"/opt/conda/envs/cf-scripts/lib/python3.11/http/client.py\", line 1395, in getresponse\n    response.begin()\n  File \"/opt/conda/envs/cf-scripts/lib/python3.11/http/client.py\", line 325, in begin\n    version, status, reason = self._read_status()\n                              ^^^^^^^^^^^^^^^^^^^\n  File \"/opt/conda/envs/cf-scripts/lib/python3.11/http/client.py\", line 294, in _read_status\n    raise RemoteDisconnected(\"Remote end closed connection without\"\nhttp.client.RemoteDisconnected: Remote end closed connection without response\n\nDuring handling of the above exception, another exception occurred:\n\nTraceback (most recent call last):\n  File \"/opt/conda/envs/cf-scripts/lib/python3.11/site-packages/requests/adapters.py\", line 667, in send\n    resp = conn.urlopen(\n           ^^^^^^^^^^^^^\n  File \"/opt/conda/envs/cf-scripts/lib/python3.11/site-packages/urllib3/connectionpool.py\", line 801, in urlopen\n    retries = retries.increment(\n              ^^^^^^^^^^^^^^^^^^\n  File \"/opt/conda/envs/cf-scripts/lib/python3.11/site-packages/urllib3/util/retry.py\", line 552, in increment\n    raise six.reraise(type(error), error, _stacktrace)\n          ^^^^^^^^^^^^^^^^^^^^^^^^^^^^^^^^^^^^^^^^^^^^\n  File \"/opt/conda/envs/cf-scripts/lib/python3.11/site-packages/urllib3/packages/six.py\", line 769, in reraise\n    raise value.with_traceback(tb)\n  File \"/opt/conda/envs/cf-scripts/lib/python3.11/site-packages/urllib3/connectionpool.py\", line 715, in urlopen\n    httplib_response = self._make_request(\n                       ^^^^^^^^^^^^^^^^^^^\n  File \"/opt/conda/envs/cf-scripts/lib/python3.11/site-packages/urllib3/connectionpool.py\", line 467, in _make_request\n    six.raise_from(e, None)\n  File \"<string>\", line 3, in raise_from\n  File \"/opt/conda/envs/cf-scripts/lib/python3.11/site-packages/urllib3/connectionpool.py\", line 462, in _make_request\n    httplib_response = conn.getresponse()\n                       ^^^^^^^^^^^^^^^^^^\n  File \"/opt/conda/envs/cf-scripts/lib/python3.11/http/client.py\", line 1395, in getresponse\n    response.begin()\n  File \"/opt/conda/envs/cf-scripts/lib/python3.11/http/client.py\", line 325, in begin\n    version, status, reason = self._read_status()\n                              ^^^^^^^^^^^^^^^^^^^\n  File \"/opt/conda/envs/cf-scripts/lib/python3.11/http/client.py\", line 294, in _read_status\n    raise RemoteDisconnected(\"Remote end closed connection without\"\nurllib3.exceptions.ProtocolError: ('Connection aborted.', RemoteDisconnected('Remote end closed connection without response'))\n\nDuring handling of the above exception, another exception occurred:\n\nTraceback (most recent call last):\n  File \"/opt/autotick-bot/conda_forge_tick/container_cli.py\", line 119, in _run_bot_task\n    data = func(attrs=attrs, **kwargs)\n           ^^^^^^^^^^^^^^^^^^^^^^^^^^^\n  File \"/opt/autotick-bot/conda_forge_tick/container_cli.py\", line 197, in _migrate_feedstock\n    from conda_forge_tick.migrators import make_from_lazy_json_data\n  File \"/opt/autotick-bot/conda_forge_tick/migrators/__init__.py\", line 24, in <module>\n    from .dep_updates import DependencyUpdateMigrator\n  File \"/opt/autotick-bot/conda_forge_tick/migrators/dep_updates.py\", line 6, in <module>\n    from conda_forge_tick.update_deps import apply_dep_update, get_dep_updates_and_hints\n  File \"/opt/autotick-bot/conda_forge_tick/update_deps.py\", line 68, in <module>\n    r = requests.get(\n        ^^^^^^^^^^^^^\n  File \"/opt/conda/envs/cf-scripts/lib/python3.11/site-packages/requests/api.py\", line 73, in get\n    return request(\"get\", url, params=params, **kwargs)\n           ^^^^^^^^^^^^^^^^^^^^^^^^^^^^^^^^^^^^^^^^^^^^\n  File \"/opt/conda/envs/cf-scripts/lib/python3.11/site-packages/requests/api.py\", line 59, in request\n    return session.request(method=method, url=url, **kwargs)\n           ^^^^^^^^^^^^^^^^^^^^^^^^^^^^^^^^^^^^^^^^^^^^^^^^^\n  File \"/opt/conda/envs/cf-scripts/lib/python3.11/site-packages/requests/sessions.py\", line 589, in request\n    resp = self.send(prep, **send_kwargs)\n           ^^^^^^^^^^^^^^^^^^^^^^^^^^^^^^\n  File \"/opt/conda/envs/cf-scripts/lib/python3.11/site-packages/requests/sessions.py\", line 703, in send\n    r = adapter.send(request, **kwargs)\n        ^^^^^^^^^^^^^^^^^^^^^^^^^^^^^^^\n  File \"/opt/conda/envs/cf-scripts/lib/python3.11/site-packages/requests/adapters.py\", line 682, in send\n    raise ConnectionError(err, request=request)\nrequests.exceptions.ConnectionError: ('Connection aborted.', RemoteDisconnected('Remote end closed connection without response'))\n"
 },
 "smithy_version": "3.30.4"
}