{
 "bad": false,
 "pre_pr_migrator_attempts": {
  "noarch_python_min": 8
 },
 "pre_pr_migrator_status": {
  "noarch_python_min": "bot error (<a href=\"https://github.com/regro/cf-scripts/actions/runs/13003569924\">bot CI job</a>): main:\nTraceback (most recent call last):\n  File \"/opt/conda/envs/cf-scripts/lib/python3.11/site-packages/conda_forge_feedstock_ops/__main__.py\", line 104, in _run_bot_task\n    data = func(**kwargs)\n           ^^^^^^^^^^^^^^\n  File \"/opt/conda/envs/cf-scripts/lib/python3.11/site-packages/conda_forge_feedstock_ops/__main__.py\", line 216, in _rerender_feedstock\n    msg = rerender_local(fs_dir, **kwargs)\n          ^^^^^^^^^^^^^^^^^^^^^^^^^^^^^^^^\n  File \"/opt/conda/envs/cf-scripts/lib/python3.11/site-packages/conda_forge_feedstock_ops/rerender.py\", line 255, in rerender_local\n    raise RuntimeError(f\"Failed to rerender.\noutput: {ret.stdout}\n\")\nRuntimeError: Failed to rerender.\noutput: INFO:conda_smithy.configure_feedstock:Downloading conda-forge-pinning-2025.01.28.04.06.09\nTraceback (most recent call last):\n  File \"/opt/conda/envs/cf-scripts/bin/conda-smithy\", line 10, in <module>\n    sys.exit(main())\n             ^^^^^^\n  File \"/opt/conda/envs/cf-scripts/lib/python3.11/site-packages/conda_smithy/cli.py\", line 767, in main\n    args.subcommand_func(args)\n  File \"/opt/conda/envs/cf-scripts/lib/python3.11/site-packages/conda_smithy/cli.py\", line 610, in __call__\n    self._call(args, args.temporary_directory)\n  File \"/opt/conda/envs/cf-scripts/lib/python3.11/site-packages/conda_smithy/cli.py\", line 613, in _call\n    configure_feedstock.main(\n  File \"/opt/conda/envs/cf-scripts/lib/python3.11/site-packages/conda_smithy/configure_feedstock.py\", line 2858, in main\n    exclusive_config_file, cf_pinning_ver = get_cached_cfp_file_path(\n                                            ^^^^^^^^^^^^^^^^^^^^^^^^^\n  File \"/opt/conda/envs/cf-scripts/lib/python3.11/site-packages/conda_smithy/configure_feedstock.py\", line 2678, in get_cached_cfp_file_path\n    get_cfp_file_path(smithy_cache)\n  File \"/opt/conda/envs/cf-scripts/lib/python3.11/site-packages/conda_smithy/configure_feedstock.py\", line 2619, in get_cfp_file_path\n    response.raise_for_status()\n  File \"/opt/conda/envs/cf-scripts/lib/python3.11/site-packages/requests/models.py\", line 1024, in raise_for_status\n    raise HTTPError(http_error_msg, response=self)\nrequests.exceptions.HTTPError: 502 Server Error: Bad Gateway for url: https://api.anaconda.org/download/conda-forge/conda-forge-pinning/2025.01.28.04.06.09/noarch/conda-forge-pinning-2025.01.28.04.06.09-hd8ed1ab_0.conda\n\n\n"
 }
}